Workbook

Sheet Resumen Ejecutivo
A1: Solución Energética — GRUPO POSADAS / FIDEICOMISO F/1596 (FIBRAHOTEL)
A2: Resumen ejecutivo · pre-IVA · valores del motor CFE Brain (verificado sin errores) · finanzas 100% en vivo desde Supuestos
A4: RECOMENDACIÓN POR PROYECTO
A5: Sitio | B5: Tarifa Actual $/año | C5: Ahorro bruto $/año | D5: Ahorro % | E5: Inversión $ | F5: TIR compra | G5: PPA $/kWh | H5: Benef. cliente PPA a1 $ | I5: Ahorro cliente % (PPA a1)
A6: Médano / Cabo San Lucas (Posadas F/1596) | B6: ='Médano - Cabo San Lucas (Pos'!$E$38*'Médano - Cabo San Lucas (Pos'!$B$39 | C6: ='Médano - Cabo San Lucas (Pos'!$J$38*'Médano - Cabo San Lucas (Pos'!$B$39 | D6: =C6/B6 | E6: ='Médano - Cabo San Lucas (Pos'!$B$22 | F6: ='Médano - Cabo San Lucas (Pos'!$B$64 | G6: =Supuestos!$I$26 | H6: ='Médano - Cabo San Lucas (Pos'!$J$43 | I6: ='Médano - Cabo San Lucas (Pos'!$J$43/'Médano - Cabo San Lucas (Pos'!$B$43
A7: Fairfield Inn Vallejo (F/1596) | B7: ='Fairfield Inn Vallejo (F-159'!$E$38*'Fairfield Inn Vallejo (F-159'!$B$39 | C7: ='Fairfield Inn Vallejo (F-159'!$J$38*'Fairfield Inn Vallejo (F-159'!$B$39 | D7: =C7/B7 | E7: ='Fairfield Inn Vallejo (F-159'!$B$22 | F7: ='Fairfield Inn Vallejo (F-159'!$B$64 | G7: =Supuestos!$I$27 | H7: ='Fairfield Inn Vallejo (F-159'!$J$43 | I7: ='Fairfield Inn Vallejo (F-159'!$J$43/'Fairfield Inn Vallejo (F-159'!$B$43
A8: Fiesta Americana Condesa Cancún | B8: ='Fiesta Americana Condesa Can'!$E$38*'Fiesta Americana Condesa Can'!$B$39 | C8: ='Fiesta Americana Condesa Can'!$J$38*'Fiesta Americana Condesa Can'!$B$39 | D8: =C8/B8 | E8: ='Fiesta Americana Condesa Can'!$B$22 | F8: ='Fiesta Americana Condesa Can'!$B$64 | G8: =Supuestos!$I$28 | H8: ='Fiesta Americana Condesa Can'!$J$43 | I8: ='Fiesta Americana Condesa Can'!$J$43/'Fiesta Americana Condesa Can'!$B$43
A9: Fiesta Inn Periférico Sur (CDMX) | B9: ='Fiesta Inn Periférico Sur (C'!$E$38*'Fiesta Inn Periférico Sur (C'!$B$39 | C9: ='Fiesta Inn Periférico Sur (C'!$J$38*'Fiesta Inn Periférico Sur (C'!$B$39 | D9: =C9/B9 | E9: ='Fiesta Inn Periférico Sur (C'!$B$22 | F9: ='Fiesta Inn Periférico Sur (C'!$B$64 | G9: =Supuestos!$I$29 | H9: ='Fiesta Inn Periférico Sur (C'!$J$43 | I9: ='Fiesta Inn Periférico Sur (C'!$J$43/'Fiesta Inn Periférico Sur (C'!$B$43
A10: Fiesta Americana Viaducto Aeropuerto (CDMX) | B10: ='Fiesta Americana Viaducto Ae'!$E$38*'Fiesta Americana Viaducto Ae'!$B$39 | C10: ='Fiesta Americana Viaducto Ae'!$J$38*'Fiesta Americana Viaducto Ae'!$B$39 | D10: =C10/B10 | E10: ='Fiesta Americana Viaducto Ae'!$B$22 | F10: ='Fiesta Americana Viaducto Ae'!$B$64 | G10: =Supuestos!$I$30 | H10: ='Fiesta Americana Viaducto Ae'!$J$43 | I10: ='Fiesta Americana Viaducto Ae'!$J$43/'Fiesta Americana Viaducto Ae'!$B$43
A11: PORTAFOLIO | B11: =SUM(B6:B10) | C11: =SUM(C6:C10) | D11: =C11/B11 | E11: =SUM(E6:E10) | H11: =SUM(H6:H10) | I11: =H11/('Médano - Cabo San Lucas (Pos'!$B$43+'Fairfield Inn Vallejo (F-159'!$B$43+'Fiesta Americana Condesa Can'!$B$43+'Fiesta Inn Periférico Sur (C'!$B$43+'Fiesta Americana Viaducto Ae'!$B$43)
A13: INDICADORES CLAVE
A14: Gasto eléctrico actual $/año | C14: Ahorro proyecto $/año | E14: Ahorro % del gasto | G14: Ahorro cliente % (PPA a1) | I14: Inversión total (compra) $
A15: =B11 | C15: =C11 | E15: =C11/B11 | G15: =I11 | I15: =E11

Sheet Supuestos
A1: SUPUESTOS — Panel de control en vivo
A2: LIBRO 100% EN VIVO: financieras (AZUL) y dimensionamiento (ÁMBAR) recalculan todo — el motor mensual de cada hoja es fórmula sobre sus datos de recibo (§6).
A3: A. SUPUESTOS GLOBALES
A4: EPC PV (USD/Wp) | B4: 0.75
A5: Tipo de cambio (MXN/USD) | B5: 17.55
A6: EPC BESS (USD/kWh) | B6: 280
A7: WACC / descuento | B7: 0.12
A8: Escalación CFE / año | B8: 0.05
A9: Escalación PPA / año | B9: 0.05
A10: Disponibilidad (factor SaaS) | B10: 0.75
A11: Degradación PV año 1 | B11: 0.01
A12: Degradación PV año 2+ | B12: 0.004
A13: Degradación BESS / año | B13: 0.0125
A14: Comisión BESS financiador | B14: 0.5
A15: Horizonte (años) | B15: 20
... A22: Plazo BESS / comisión (años) | B22: 15
A24: B. VARIABLES POR PROYECTO (AZUL = financiero · ÁMBAR = dimensionamiento)
A25: Proyecto | B25: PV kWp | C25: BESS kW | D25: BESS kWh | E25: FP corr | F25: PV USD/Wp | G25: BESS USD/kWh | H25: Capacitor $ | I25: PPA $/kWh | J25: PPA plazo | K25: Comisión % | L25: TIR compra | M25: TIR financiador | N25: Ahorro bruto/año $ | O25: Ahorro bruto % | P25: Ahorro cliente % (PPA a1)
A26: Médano / Cabo San Lucas (Posadas F/1596) | B26: 290.6 | C26: 0 | D26: 0 | E26: Sí | F26: 0.75 | G26: 280 | H26: 0 | I26: 1.5543 | J26: 15 | K26: 0.5 | L26: ='Médano - Cabo San Lucas (Pos'!$B$64 | M26: ='Médano - Cabo San Lucas (Pos'!$B$65 | N26: ='Médano - Cabo San Lucas (Pos'!$J$38 | O26: ='Médano - Cabo San Lucas (Pos'!$J$38/'Médano - Cabo San Lucas (Pos'!$E$38 | P26: ='Médano - Cabo San Lucas (Pos'!$J$43/'Médano - Cabo San Lucas (Pos'!$B$43
A27: Fairfield Inn Vallejo (F/1596) | B27: 96.9 | C27: 186 | D27: 743 | E27: Sí | F27: 0.75 | G27: 280 | H27: 0 | I27: 4.4867 | J27: 15 | K27: 0.5 | L27: ='Fairfield Inn Vallejo (F-159'!$B$64 | M27: ='Fairfield Inn Vallejo (F-159'!$B$65 | N27: ='Fairfield Inn Vallejo (F-159'!$J$38 | O27: ='Fairfield Inn Vallejo (F-159'!$J$38/'Fairfield Inn Vallejo (F-159'!$E$38 | P27: ='Fairfield Inn Vallejo (F-159'!$J$43/'Fairfield Inn Vallejo (F-159'!$B$43
A28: Fiesta Americana Condesa Cancún | B28: 194.48 | C28: 1503 | D28: 2940 | E28: Sí | F28: 0.75 | G28: 280 | H28: 0 | I28: 4.352 | J28: 15 | K28: 0.5 | L28: ='Fiesta Americana Condesa Can'!$B$64 | M28: ='Fiesta Americana Condesa Can'!$B$65 | N28: ='Fiesta Americana Condesa Can'!$J$38 | O28: ='Fiesta Americana Condesa Can'!$J$38/'Fiesta Americana Condesa Can'!$E$38 | P28: ='Fiesta Americana Condesa Can'!$J$43/'Fiesta Americana Condesa Can'!$B$43
A29: Fiesta Inn Periférico Sur (CDMX) | B29: 348.8 | C29: 207 | D29: 827 | E29: Sí | F29: 0.75 | G29: 280 | H29: 0 | I29: 2.8194 | J29: 15 | K29: 0.5 | L29: ='Fiesta Inn Periférico Sur (C'!$B$64 | M29: ='Fiesta Inn Periférico Sur (C'!$B$65 | N29: ='Fiesta Inn Periférico Sur (C'!$J$38 | O29: ='Fiesta Inn Periférico Sur (C'!$J$38/'Fiesta Inn Periférico Sur (C'!$E$38 | P29: ='Fiesta Inn Periférico Sur (C'!$J$43/'Fiesta Inn Periférico Sur (C'!$B$43
A30: Fiesta Americana Viaducto Aeropuerto (CDMX) | B30: 233.9 | C30: 254 | D30: 1017 | E30: Sí | F30: 0.75 | G30: 280 | H30: 0 | I30: 3.3408 | J30: 15 | K30: 0.5 | L30: ='Fiesta Americana Viaducto Ae'!$B$64 | M30: ='Fiesta Americana Viaducto Ae'!$B$65 | N30: ='Fiesta Americana Viaducto Ae'!$J$38 | O30: ='Fiesta Americana Viaducto Ae'!$J$38/'Fiesta Americana Viaducto Ae'!$E$38 | P30: ='Fiesta Americana Viaducto Ae'!$J$43/'Fiesta Americana Viaducto Ae'!$B$43
A31: PORTAFOLIO | B31: =SUM(B26:B30) | C31: =SUM(C26:C30) | D31: =SUM(D26:D30) | H31: =SUM(H26:H30) | N31: =SUM(N26:N30) | O31: =N31/('Médano - Cabo San Lucas (Pos'!$E$38+'Fairfield Inn Vallejo (F-159'!$E$38+'Fiesta Americana Condesa Can'!$E$38+'Fiesta Inn Periférico Sur (C'!$E$38+'Fiesta Americana Viaducto Ae'!$E$38) | P31: =('Médano - Cabo San Lucas (Pos'!$J$43+'Fairfield Inn Vallejo (F-159'!$J$43+'Fiesta Americana Condesa Can'!$J$43+'Fiesta Inn Periférico Sur (C'!$J$43+'Fiesta Americana Viaducto Ae'!$J$43)/('Médano - Cabo San Lucas (Pos'!$B$43+'Fairfield Inn Vallejo (F-159'!$B$43+'Fiesta Americana Condesa Can'!$B$43+'Fiesta Inn Periférico Sur (C'!$B$43+'Fiesta Americana Viaducto Ae'!$B$43)

Sheet Médano - Cabo San Lucas (Pos
A1: Médano / Cabo San Lucas (Posadas F/1596) — Memoria de cálculo y propuesta energética
A2: RPU 008111000167 · GDMTH BCS · Demanda contratada 326 kW · 12 meses de recibo
A3: Régimen: GENERADOR EXENTO — Medición Neta (sin permiso; Art. 30 LSE; RES/142/2017)
A5: PARÁMETROS (desde Supuestos — edítalos ahí)
A6: PV kWp | B6: =Supuestos!$B$26 | C6: BESS kW | D6: =Supuestos!$C$26 | E6: BESS kWh | F6: =Supuestos!$D$26 | G6: FP corrección | H6: =Supuestos!$E$26 | I6: Entrega útil kWh | J6: =Supuestos!$D$26*Supuestos!$B$17*SQRT(Supuestos!$B$18) | K6: FC umbral | L6: 0.57
A8: 1. ESTRUCTURA DE COSTO Y AHORRO (pre-IVA, año base · fórmulas vivas ← §3)
A9: Concepto | B9: $ / año | C9: Nota
A10: Tarifa Actual (CFE pleno, sin proyecto) | B10: =$E$38*$B$39 | C10: Σ recibos × anualización
A11: (−) Ahorro PV (energía + demanda) | B11: =$F$38*$B$39 | C11: intermedio + umbral
A12: (−) Ahorro BESS (punta + arbitraje) | B12: =$G$38*$B$39 | C12: recorte punta + arbitraje (incl. claw)
A13: (−) Ahorro FP (corrección) | B13: =$H$38*$B$39 | C13: multa factor de potencia
A14: (=) Costo neto con proyecto | B14: =B10-B11-B12-B13
A15: Ahorro proyecto / año | B15: =B11+B12+B13
A16: Ahorro % | B16: =B15/B10
A18: 2. CAPEX (fórmulas vivas desde Supuestos)
A19: CAPEX PV | B19: =Supuestos!$B$26*1000*Supuestos!$F$26*Supuestos!$B$5
A20: CAPEX BESS | B20: =Supuestos!$D$26*Supuestos!$G$26*Supuestos!$B$5
A21: CAPEX capacitor (FP) | B21: =Supuestos!$H$26
A22: CAPEX TOTAL | B22: =B19+B20+B21
A24: 3. RESUMEN MENSUAL — Tarifa Actual vs Con Proyecto (fórmulas vivas ← §6 y Supuestos)
A25: Mes | B25: kWh Consumo | C25: Gen PV kWh | D25: BESS desc kWh | E25: Tarifa Actual $ | F25: Ah PV $ | G25: Ah BESS $ | H25: Ah FP $ | I25: Costo c/proy $ | J25: Ahorro $ | K25: Ahorro %
A26: =A80 | B26: =V80 | C26: =Supuestos!$B$26*S80 | D26: =MIN($J$6*U80,E80) | E26: =SUM(J80:Q80) | F26: =(MIN(C26,D80)*Y80+(MIN(H80,AA80)-MIN(H80,(V80-MIN(C26,D80))/($B$80*24*$L$6)))*AB80)*IF(Q80<0,1+Q80/SUM(J80:P80),1) | G26: =((MIN(H80,(V80-MIN(C26,D80))/($B$80*24*$L$6))-MIN(MAX(H80-MIN(Supuestos!$C$26,IF(T80>0,$J$6/T80,0)),0),(V80-MIN(C26,D80))/($B$80*24*$L$6)))*AB80+D26*Z80-D26/Supuestos!$B$18*X80)*IF(Q80<0,1+Q80/SUM(J80:P80),1) | H26: =IF(Supuestos!$E$26="Sí",R80,0) | I26: =E26-J26 | J26: =F26+G26+H26 | K26: =J26/E26
A27: =A81 | B27: =V81 | C27: =Supuestos!$B$26*S81 | D27: =MIN($J$6*U81,E81) | E27: =SUM(J81:Q81) | F27: =(MIN(C27,D81)*Y81+(MIN(H81,AA81)-MIN(H81,(V81-MIN(C27,D81))/($B$81*24*$L$6)))*AB81)*IF(Q81<0,1+Q81/SUM(J81:P81),1) | G27: =((MIN(H81,(V81-MIN(C27,D81))/($B$81*24*$L$6))-MIN(MAX(H81-MIN(Supuestos!$C$26,IF(T81>0,$J$6/T81,0)),0),(V81-MIN(C27,D81))/($B$81*24*$L$6)))*AB81+D27*Z81-D27/Supuestos!$B$18*X81)*IF(Q81<0,1+Q81/SUM(J81:P81),1) | H27: =IF(Supuestos!$E$26="Sí",R81,0) | I27: =E27-J27 | J27: =F27+G27+H27 | K27: =J27/E27
A28: =A82 | B28: =V82 | C28: =Supuestos!$B$26*S82 | D28: =MIN($J$6*U82,E82) | E28: =SUM(J82:Q82) | F28: =(MIN(C28,D82)*Y82+(MIN(H82,AA82)-MIN(H82,(V82-MIN(C28,D82))/($B$82*24*$L$6)))*AB82)*IF(Q82<0,1+Q82/SUM(J82:P82),1) | G28: =((MIN(H82,(V82-MIN(C28,D82))/($B$82*24*$L$6))-MIN(MAX(H82-MIN(Supuestos!$C$26,IF(T82>0,$J$6/T82,0)),0),(V82-MIN(C28,D82))/($B$82*24*$L$6)))*AB82+D28*Z82-D28/Supuestos!$B$18*X82)*IF(Q82<0,1+Q82/SUM(J82:P82),1) | H28: =IF(Supuestos!$E$26="Sí",R82,0) | I28: =E28-J28 | J28: =F28+G28+H28 | K28: =J28/E28
A29: =A83 | B29: =V83 | C29: =Supuestos!$B$26*S83 | D29: =MIN($J$6*U83,E83) | E29: =SUM(J83:Q83) | F29: =(MIN(C29,D83)*Y83+(MIN(H83,AA83)-MIN(H83,(V83-MIN(C29,D83))/($B$83*24*$L$6)))*AB83)*IF(Q83<0,1+Q83/SUM(J83:P83),1) | G29: =((MIN(H83,(V83-MIN(C29,D83))/($B$83*24*$L$6))-MIN(MAX(H83-MIN(Supuestos!$C$26,IF(T83>0,$J$6/T83,0)),0),(V83-MIN(C29,D83))/($B$83*24*$L$6)))*AB83+D29*Z83-D29/Supuestos!$B$18*X83)*IF(Q83<0,1+Q83/SUM(J83:P83),1) | H29: =IF(Supuestos!$E$26="Sí",R83,0) | I29: =E29-J29 | J29: =F29+G29+H29 | K29: =J29/E29
A30: =A84 | B30: =V84 | C30: =Supuestos!$B$26*S84 | D30: =MIN($J$6*U84,E84) | E30: =SUM(J84:Q84) | F30: =(MIN(C30,D84)*Y84+(MIN(H84,AA84)-MIN(H84,(V84-MIN(C30,D84))/($B$84*24*$L$6)))*AB84)*IF(Q84<0,1+Q84/SUM(J84:P84),1) | G30: =((MIN(H84,(V84-MIN(C30,D84))/($B$84*24*$L$6))-MIN(MAX(H84-MIN(Supuestos!$C$26,IF(T84>0,$J$6/T84,0)),0),(V84-MIN(C30,D84))/($B$84*24*$L$6)))*AB84+D30*Z84-D30/Supuestos!$B$18*X84)*IF(Q84<0,1+Q84/SUM(J84:P84),1) | H30: =IF(Supuestos!$E$26="Sí",R84,0) | I30: =E30-J30 | J30: =F30+G30+H30 | K30: =J30/E30
A31: =A85 | B31: =V85 | C31: =Supuestos!$B$26*S85 | D31: =MIN($J$6*U85,E85) | E31: =SUM(J85:Q85) | F31: =(MIN(C31,D85)*Y85+(MIN(H85,AA85)-MIN(H85,(V85-MIN(C31,D85))/($B$85*24*$L$6)))*AB85)*IF(Q85<0,1+Q85/SUM(J85:P85),1) | G31: =((MIN(H85,(V85-MIN(C31,D85))/($B$85*24*$L$6))-MIN(MAX(H85-MIN(Supuestos!$C$26,IF(T85>0,$J$6/T85,0)),0),(V85-MIN(C31,D85))/($B$85*24*$L$6)))*AB85+D31*Z85-D31/Supuestos!$B$18*X85)*IF(Q85<0,1+Q85/SUM(J85:P85),1) | H31: =IF(Supuestos!$E$26="Sí",R85,0) | I31: =E31-J31 | J31: =F31+G31+H31 | K31: =J31/E31
A32: =A86 | B32: =V86 | C32: =Supuestos!$B$26*S86 | D32: =MIN($J$6*U86,E86) | E32: =SUM(J86:Q86) | F32: =(MIN(C32,D86)*Y86+(MIN(H86,AA86)-MIN(H86,(V86-MIN(C32,D86))/($B$86*24*$L$6)))*AB86)*IF(Q86<0,1+Q86/SUM(J86:P86),1) | G32: =((MIN(H86,(V86-MIN(C32,D86))/($B$86*24*$L$6))-MIN(MAX(H86-MIN(Supuestos!$C$26,IF(T86>0,$J$6/T86,0)),0),(V86-MIN(C32,D86))/($B$86*24*$L$6)))*AB86+D32*Z86-D32/Supuestos!$B$18*X86)*IF(Q86<0,1+Q86/SUM(J86:P86),1) | H32: =IF(Supuestos!$E$26="Sí",R86,0) | I32: =E32-J32 | J32: =F32+G32+H32 | K32: =J32/E32
A33: =A87 | B33: =V87 | C33: =Supuestos!$B$26*S87 | D33: =MIN($J$6*U87,E87) | E33: =SUM(J87:Q87) | F33: =(MIN(C33,D87)*Y87+(MIN(H87,AA87)-MIN(H87,(V87-MIN(C33,D87))/($B$87*24*$L$6)))*AB87)*IF(Q87<0,1+Q87/SUM(J87:P87),1) | G33: =((MIN(H87,(V87-MIN(C33,D87))/($B$87*24*$L$6))-MIN(MAX(H87-MIN(Supuestos!$C$26,IF(T87>0,$J$6/T87,0)),0),(V87-MIN(C33,D87))/($B$87*24*$L$6)))*AB87+D33*Z87-D33/Supuestos!$B$18*X87)*IF(Q87<0,1+Q87/SUM(J87:P87),1) | H33: =IF(Supuestos!$E$26="Sí",R87,0) | I33: =E33-J33 | J33: =F33+G33+H33 | K33: =J33/E33
A34: =A88 | B34: =V88 | C34: =Supuestos!$B$26*S88 | D34: =MIN($J$6*U88,E88) | E34: =SUM(J88:Q88) | F34: =(MIN(C34,D88)*Y88+(MIN(H88,AA88)-MIN(H88,(V88-MIN(C34,D88))/($B$88*24*$L$6)))*AB88)*IF(Q88<0,1+Q88/SUM(J88:P88),1) | G34: =((MIN(H88,(V88-MIN(C34,D88))/($B$88*24*$L$6))-MIN(MAX(H88-MIN(Supuestos!$C$26,IF(T88>0,$J$6/T88,0)),0),(V88-MIN(C34,D88))/($B$88*24*$L$6)))*AB88+D34*Z88-D34/Supuestos!$B$18*X88)*IF(Q88<0,1+Q88/SUM(J88:P88),1) | H34: =IF(Supuestos!$E$26="Sí",R88,0) | I34: =E34-J34 | J34: =F34+G34+H34 | K34: =J34/E34
A35: =A89 | B35: =V89 | C35: =Supuestos!$B$26*S89 | D35: =MIN($J$6*U89,E89) | E35: =SUM(J89:Q89) | F35: =(MIN(C35,D89)*Y89+(MIN(H89,AA89)-MIN(H89,(V89-MIN(C35,D89))/($B$89*24*$L$6)))*AB89)*IF(Q89<0,1+Q89/SUM(J89:P89),1) | G35: =((MIN(H89,(V89-MIN(C35,D89))/($B$89*24*$L$6))-MIN(MAX(H89-MIN(Supuestos!$C$26,IF(T89>0,$J$6/T89,0)),0),(V89-MIN(C35,D89))/($B$89*24*$L$6)))*AB89+D35*Z89-D35/Supuestos!$B$18*X89)*IF(Q89<0,1+Q89/SUM(J89:P89),1) | H35: =IF(Supuestos!$E$26="Sí",R89,0) | I35: =E35-J35 | J35: =F35+G35+H35 | K35: =J35/E35
A36: =A90 | B36: =V90 | C36: =Supuestos!$B$26*S90 | D36: =MIN($J$6*U90,E90) | E36: =SUM(J90:Q90) | F36: =(MIN(C36,D90)*Y90+(MIN(H90,AA90)-MIN(H90,(V90-MIN(C36,D90))/($B$90*24*$L$6)))*AB90)*IF(Q90<0,1+Q90/SUM(J90:P90),1) | G36: =((MIN(H90,(V90-MIN(C36,D90))/($B$90*24*$L$6))-MIN(MAX(H90-MIN(Supuestos!$C$26,IF(T90>0,$J$6/T90,0)),0),(V90-MIN(C36,D90))/($B$90*24*$L$6)))*AB90+D36*Z90-D36/Supuestos!$B$18*X90)*IF(Q90<0,1+Q90/SUM(J90:P90),1) | H36: =IF(Supuestos!$E$26="Sí",R90,0) | I36: =E36-J36 | J36: =F36+G36+H36 | K36: =J36/E36
A37: =A91 | B37: =V91 | C37: =Supuestos!$B$26*S91 | D37: =MIN($J$6*U91,E91) | E37: =SUM(J91:Q91) | F37: =(MIN(C37,D91)*Y91+(MIN(H91,AA91)-MIN(H91,(V91-MIN(C37,D91))/($B$91*24*$L$6)))*AB91)*IF(Q91<0,1+Q91/SUM(J91:P91),1) | G37: =((MIN(H91,(V91-MIN(C37,D91))/($B$91*24*$L$6))-MIN(MAX(H91-MIN(Supuestos!$C$26,IF(T91>0,$J$6/T91,0)),0),(V91-MIN(C37,D91))/($B$91*24*$L$6)))*AB91+D37*Z91-D37/Supuestos!$B$18*X91)*IF(Q91<0,1+Q91/SUM(J91:P91),1) | H37: =IF(Supuestos!$E$26="Sí",R91,0) | I37: =E37-J37 | J37: =F37+G37+H37 | K37: =J37/E37
A38: TOTAL | B38: =SUM(B26:B37) | C38: =SUM(C26:C37) | D38: =SUM(D26:D37) | E38: =SUM(E26:E37) | F38: =SUM(F26:F37) | G38: =SUM(G26:G37) | H38: =SUM(H26:H37) | I38: =SUM(I26:I37) | J38: =SUM(J26:J37) | K38: =J38/E38
A39: Factor anualización (12/meses): | B39: 1
A40: 4. PROYECCIÓN 20 AÑOS — Comprar vs PPA/Ahorro compartido
A41: Año | B41: Tarifa Actual $ | C41: Ah PV $ | D41: Ah BESS $ | E41: Ah FP $ | F41: Costo c/proy $ | G41: Flujo Compra $ | H41: Pago PPA $ | I41: Comisión $ | J41: Flujo Cliente PPA $ | K41: Flujo Financiador $ | L41: Acum Compra $ | M41: Acum Cliente PPA $
A42: 0 | G42: =-B22 | K42: =-B22 | L42: =G42 | M42: 0
A43: 1 | B43: =$E$38*$B$39*(1+Supuestos!$B$8)^1 | C43: =$F$38*$B$39*(1+Supuestos!$B$8)^1*((1-Supuestos!$B$11)*(1-Supuestos!$B$12)^0) | D43: =$G$38*$B$39*(1+Supuestos!$B$8)^1*(1-Supuestos!$B$13)^1*Supuestos!$B$10 | E43: =$H$38*$B$39*(1+Supuestos!$B$8)^1 | F43: =B43-C43-D43-E43 | G43: =C43+D43+E43-(IF(1<=Supuestos!$J$26,Supuestos!$B$19*Supuestos!$B$26*(1+Supuestos!$B$8)^0,0)+IF(1<=Supuestos!$B$22,Supuestos!$B$20*Supuestos!$D$26*(1+Supuestos!$B$8)^0,0)) | H43: =IF(1<=Supuestos!$J$26,$C$38*$B$39*((1-Supuestos!$B$11)*(1-Supuestos!$B$12)^0)*Supuestos!$I$26*(1+Supuestos!$B$9)^0,0) | I43: =IF(1<=Supuestos!$B$22,D43*Supuestos!$K$26,0) | J43: =C43+D43+E43-H43-I43 | K43: =H43+I43-(IF(1<=Supuestos!$J$26,Supuestos!$B$19*Supuestos!$B$26*(1+Supuestos!$B$8)^0,0)+IF(1<=Supuestos!$B$22,Supuestos!$B$20*Supuestos!$D$26*(1+Supuestos!$B$8)^0,0))-H43*Supuestos!$B$21 | L43: =L42+G43 | M43: =M42+J43
A44: 2 | B44: =$E$38*$B$39*(1+Supuestos!$B$8)^2 | C44: =$F$38*$B$39*(1+Supuestos!$B$8)^2*((1-Supuestos!$B$11)*(1-Supuestos!$B$12)^1) | D44: =$G$38*$B$39*(1+Supuestos!$B$8)^2*(1-Supuestos!$B$13)^2*Supuestos!$B$10 | E44: =$H$38*$B$39*(1+Supuestos!$B$8)^2 | F44: =B44-C44-D44-E44 | G44: =C44+D44+E44-(IF(2<=Supuestos!$J$26,Supuestos!$B$19*Supuestos!$B$26*(1+Supuestos!$B$8)^1,0)+IF(2<=Supuestos!$B$22,Supuestos!$B$20*Supuestos!$D$26*(1+Supuestos!$B$8)^1,0)) | H44: =IF(2<=Supuestos!$J$26,$C$38*$B$39*((1-Supuestos!$B$11)*(1-Supuestos!$B$12)^1)*Supuestos!$I$26*(1+Supuestos!$B$9)^1,0) | I44: =IF(2<=Supuestos!$B$22,D44*Supuestos!$K$26,0) | J44: =C44+D44+E44-H44-I44 | K44: =H44+I44-(IF(2<=Supuestos!$J$26,Supuestos!$B$19*Supuestos!$B$26*(1+Supuestos!$B$8)^1,0)+IF(2<=Supuestos!$B$22,Supuestos!$B$20*Supuestos!$D$26*(1+Supuestos!$B$8)^1,0))-H44*Supuestos!$B$21 | L44: =L43+G44 | M44: =M43+J44
...

Sheet Fairfield Inn Vallejo (F-159
A1: Fairfield Inn Vallejo (F/1596) — Memoria de cálculo y propuesta energética
A2: RPU 573170411137 · GDMTH SIN · Demanda contratada 608 kW · 12 meses de recibo
A3: Régimen: GENERADOR EXENTO — Medición Neta (sin permiso; Art. 30 LSE; RES/142/2017)
A5: PARÁMETROS (desde Supuestos — edítalos ahí)
A6: PV kWp | B6: =Supuestos!$B$27 | C6: BESS kW | D6: =Supuestos!$C$27 | E6: BESS kWh | F6: =Supuestos!$D$27 | G6: FP corrección | H6: =Supuestos!$E$27 | I6: Entrega útil kWh | J6: =Supuestos!$D$27*Supuestos!$B$17*SQRT(Supuestos!$B$18) | K6: FC umbral | L6: 0.57
A8: 1. ESTRUCTURA DE COSTO Y AHORRO (pre-IVA, año base · fórmulas vivas ← §3)
A9: Concepto | B9: $ / año | C9: Nota
A10: Tarifa Actual (CFE pleno, sin proyecto) | B10: =$E$38*$B$39 | C10: Σ recibos × anualización
A11: (−) Ahorro PV (energía + demanda) | B11: =$F$38*$B$39 | C11: intermedio + umbral
A12: (−) Ahorro BESS (punta + arbitraje) | B12: =$G$38*$B$39 | C12: recorte punta + arbitraje (incl. claw)
A13: (−) Ahorro FP (corrección) | B13: =$H$38*$B$39 | C13: multa factor de potencia
A14: (=) Costo neto con proyecto | B14: =B10-B11-B12-B13
A15: Ahorro proyecto / año | B15: =B11+B12+B13
A16: Ahorro % | B16: =B15/B10
A18: 2. CAPEX (fórmulas vivas desde Supuestos)
A19: CAPEX PV | B19: =Supuestos!$B$27*1000*Supuestos!$F$27*Supuestos!$B$5
A20: CAPEX BESS | B20: =Supuestos!$D$27*Supuestos!$G$27*Supuestos!$B$5
A21: CAPEX capacitor (FP) | B21: =Supuestos!$H$27
A22: CAPEX TOTAL | B22: =B19+B20+B21
A24: 3. RESUMEN MENSUAL — Tarifa Actual vs Con Proyecto (fórmulas vivas ← §6 y Supuestos)
A25: Mes | B25: kWh Consumo | C25: Gen PV kWh | D25: BESS desc kWh | E25: Tarifa Actual $ | F25: Ah PV $ | G25: Ah BESS $ | H25: Ah FP $ | I25: Costo c/proy $ | J25: Ahorro $ | K25: Ahorro %
A26: =A80 | B26: =V80 | C26: =Supuestos!$B$27*S80 | D26: =MIN($J$6*U80,E80) | E26: =SUM(J80:Q80) | F26: =(MIN(C26,D80)*Y80+(MIN(H80,AA80)-MIN(H80,(V80-MIN(C26,D80))/($B$80*24*$L$6)))*AB80)*IF(Q80<0,1+Q80/SUM(J80:P80),1) | G26: =((MIN(H80,(V80-MIN(C26,D80))/($B$80*24*$L$6))-MIN(MAX(H80-MIN(Supuestos!$C$27,IF(T80>0,$J$6/T80,0)),0),(V80-MIN(C26,D80))/($B$80*24*$L$6)))*AB80+D26*Z80-D26/Supuestos!$B$18*X80)*IF(Q80<0,1+Q80/SUM(J80:P80),1) | H26: =IF(Supuestos!$E$27="Sí",R80,0) | I26: =E26-J26 | J26: =F26+G26+H26 | K26: =J26/E26
A27: =A81 | B27: =V81 | C27: =Supuestos!$B$27*S81 | D27: =MIN($J$6*U81,E81) | E27: =SUM(J81:Q81) | F27: =(MIN(C27,D81)*Y81+(MIN(H81,AA81)-MIN(H81,(V81-MIN(C27,D81))/($B$81*24*$L$6)))*AB81)*IF(Q81<0,1+Q81/SUM(J81:P81),1) | G27: =((MIN(H81,(V81-MIN(C27,D81))/($B$81*24*$L$6))-MIN(MAX(H81-MIN(Supuestos!$C$27,IF(T81>0,$J$6/T81,0)),0),(V81-MIN(C27,D81))/($B$81*24*$L$6)))*AB81+D27*Z81-D27/Supuestos!$B$18*X81)*IF(Q81<0,1+Q81/SUM(J81:P81),1) | H27: =IF(Supuestos!$E$27="Sí",R81,0) | I27: =E27-J27 | J27: =F27+G27+H27 | K27: =J27/E27
A28: =A82 | B28: =V82 | C28: =Supuestos!$B$27*S82 | D28: =MIN($J$6*U82,E82) | E28: =SUM(J82:Q82) | F28: =(MIN(C28,D82)*Y82+(MIN(H82,AA82)-MIN(H82,(V82-MIN(C28,D82))/($B$82*24*$L$6)))*AB82)*IF(Q82<0,1+Q82/SUM(J82:P82),1) | G28: =((MIN(H82,(V82-MIN(C28,D82))/($B$82*24*$L$6))-MIN(MAX(H82-MIN(Supuestos!$C$27,IF(T82>0,$J$6/T82,0)),0),(V82-MIN(C28,D82))/($B$82*24*$L$6)))*AB82+D28*Z82-D28/Supuestos!$B$18*X82)*IF(Q82<0,1+Q82/SUM(J82:P82),1) | H28: =IF(Supuestos!$E$27="Sí",R82,0) | I28: =E28-J28 | J28: =F28+G28+H28 | K28: =J28/E28
A29: =A83 | B29: =V83 | C29: =Supuestos!$B$27*S83 | D29: =MIN($J$6*U83,E83) | E29: =SUM(J83:Q83) | F29: =(MIN(C29,D83)*Y83+(MIN(H83,AA83)-MIN(H83,(V83-MIN(C29,D83))/($B$83*24*$L$6)))*AB83)*IF(Q83<0,1+Q83/SUM(J83:P83),1) | G29: =((MIN(H83,(V83-MIN(C29,D83))/($B$83*24*$L$6))-MIN(MAX(H83-MIN(Supuestos!$C$27,IF(T83>0,$J$6/T83,0)),0),(V83-MIN(C29,D83))/($B$83*24*$L$6)))*AB83+D29*Z83-D29/Supuestos!$B$18*X83)*IF(Q83<0,1+Q83/SUM(J83:P83),1) | H29: =IF(Supuestos!$E$27="Sí",R83,0) | I29: =E29-J29 | J29: =F29+G29+H29 | K29: =J29/E29
A30: =A84 | B30: =V84 | C30: =Supuestos!$B$27*S84 | D30: =MIN($J$6*U84,E84) | E30: =SUM(J84:Q84) | F30: =(MIN(C30,D84)*Y84+(MIN(H84,AA84)-MIN(H84,(V84-MIN(C30,D84))/($B$84*24*$L$6)))*AB84)*IF(Q84<0,1+Q84/SUM(J84:P84),1) | G30: =((MIN(H84,(V84-MIN(C30,D84))/($B$84*24*$L$6))-MIN(MAX(H84-MIN(Supuestos!$C$27,IF(T84>0,$J$6/T84,0)),0),(V84-MIN(C30,D84))/($B$84*24*$L$6)))*AB84+D30*Z84-D30/Supuestos!$B$18*X84)*IF(Q84<0,1+Q84/SUM(J84:P84),1) | H30: =IF(Supuestos!$E$27="Sí",R84,0) | I30: =E30-J30 | J30: =F30+G30+H30 | K30: =J30/E30
A31: =A85 | B31: =V85 | C31: =Supuestos!$B$27*S85 | D31: =MIN($J$6*U85,E85) | E31: =SUM(J85:Q85) | F31: =(MIN(C31,D85)*Y85+(MIN(H85,AA85)-MIN(H85,(V85-MIN(C31,D85))/($B$85*24*$L$6)))*AB85)*IF(Q85<0,1+Q85/SUM(J85:P85),1) | G31: =((MIN(H85,(V85-MIN(C31,D85))/($B$85*24*$L$6))-MIN(MAX(H85-MIN(Supuestos!$C$27,IF(T85>0,$J$6/T85,0)),0),(V85-MIN(C31,D85))/($B$85*24*$L$6)))*AB85+D31*Z85-D31/Supuestos!$B$18*X85)*IF(Q85<0,1+Q85/SUM(J85:P85),1) | H31: =IF(Supuestos!$E$27="Sí",R85,0) | I31: =E31-J31 | J31: =F31+G31+H31 | K31: =J31/E31
A32: =A86 | B32: =V86 | C32: =Supuestos!$B$27*S86 | D32: =MIN($J$6*U86,E86) | E32: =SUM(J86:Q86) | F32: =(MIN(C32,D86)*Y86+(MIN(H86,AA86)-MIN(H86,(V86-MIN(C32,D86))/($B$86*24*$L$6)))*AB86)*IF(Q86<0,1+Q86/SUM(J86:P86),1) | G32: =((MIN(H86,(V86-MIN(C32,D86))/($B$86*24*$L$6))-MIN(MAX(H86-MIN(Supuestos!$C$27,IF(T86>0,$J$6/T86,0)),0),(V86-MIN(C32,D86))/($B$86*24*$L$6)))*AB86+D32*Z86-D32/Supuestos!$B$18*X86)*IF(Q86<0,1+Q86/SUM(J86:P86),1) | H32: =IF(Supuestos!$E$27="Sí",R86,0) | I32: =E32-J32 | J32: =F32+G32+H32 | K32: =J32/E32
A33: =A87 | B33: =V87 | C33: =Supuestos!$B$27*S87 | D33: =MIN($J$6*U87,E87) | E33: =SUM(J87:Q87) | F33: =(MIN(C33,D87)*Y87+(MIN(H87,AA87)-MIN(H87,(V87-MIN(C33,D87))/($B$87*24*$L$6)))*AB87)*IF(Q87<0,1+Q87/SUM(J87:P87),1) | G33: =((MIN(H87,(V87-MIN(C33,D87))/($B$87*24*$L$6))-MIN(MAX(H87-MIN(Supuestos!$C$27,IF(T87>0,$J$6/T87,0)),0),(V87-MIN(C33,D87))/($B$87*24*$L$6)))*AB87+D33*Z87-D33/Supuestos!$B$18*X87)*IF(Q87<0,1+Q87/SUM(J87:P87),1) | H33: =IF(Supuestos!$E$27="Sí",R87,0) | I33: =E33-J33 | J33: =F33+G33+H33 | K33: =J33/E33
A34: =A88 | B34: =V88 | C34: =Supuestos!$B$27*S88 | D34: =MIN($J$6*U88,E88) | E34: =SUM(J88:Q88) | F34: =(MIN(C34,D88)*Y88+(MIN(H88,AA88)-MIN(H88,(V88-MIN(C34,D88))/($B$88*24*$L$6)))*AB88)*IF(Q88<0,1+Q88/SUM(J88:P88),1) | G34: =((MIN(H88,(V88-MIN(C34,D88))/($B$88*24*$L$6))-MIN(MAX(H88-MIN(Supuestos!$C$27,IF(T88>0,$J$6/T88,0)),0),(V88-MIN(C34,D88))/($B$88*24*$L$6)))*AB88+D34*Z88-D34/Supuestos!$B$18*X88)*IF(Q88<0,1+Q88/SUM(J88:P88),1) | H34: =IF(Supuestos!$E$27="Sí",R88,0) | I34: =E34-J34 | J34: =F34+G34+H34 | K34: =J34/E34
A35: =A89 | B35: =V89 | C35: =Supuestos!$B$27*S89 | D35: =MIN($J$6*U89,E89) | E35: =SUM(J89:Q89) | F35: =(MIN(C35,D89)*Y89+(MIN(H89,AA89)-MIN(H89,(V89-MIN(C35,D89))/($B$89*24*$L$6)))*AB89)*IF(Q89<0,1+Q89/SUM(J89:P89),1) | G35: =((MIN(H89,(V89-MIN(C35,D89))/($B$89*24*$L$6))-MIN(MAX(H89-MIN(Supuestos!$C$27,IF(T89>0,$J$6/T89,0)),0),(V89-MIN(C35,D89))/($B$89*24*$L$6)))*AB89+D35*Z89-D35/Supuestos!$B$18*X89)*IF(Q89<0,1+Q89/SUM(J89:P89),1) | H35: =IF(Supuestos!$E$27="Sí",R89,0) | I35: =E35-J35 | J35: =F35+G35+H35 | K35: =J35/E35
A36: =A90 | B36: =V90 | C36: =Supuestos!$B$27*S90 | D36: =MIN($J$6*U90,E90) | E36: =SUM(J90:Q90) | F36: =(MIN(C36,D90)*Y90+(MIN(H90,AA90)-MIN(H90,(V90-MIN(C36,D90))/($B$90*24*$L$6)))*AB90)*IF(Q90<0,1+Q90/SUM(J90:P90),1) | G36: =((MIN(H90,(V90-MIN(C36,D90))/($B$90*24*$L$6))-MIN(MAX(H90-MIN(Supuestos!$C$27,IF(T90>0,$J$6/T90,0)),0),(V90-MIN(C36,D90))/($B$90*24*$L$6)))*AB90+D36*Z90-D36/Supuestos!$B$18*X90)*IF(Q90<0,1+Q90/SUM(J90:P90),1) | H36: =IF(Supuestos!$E$27="Sí",R90,0) | I36: =E36-J36 | J36: =F36+G36+H36 | K36: =J36/E36
A37: =A91 | B37: =V91 | C37: =Supuestos!$B$27*S91 | D37: =MIN($J$6*U91,E91) | E37: =SUM(J91:Q91) | F37: =(MIN(C37,D91)*Y91+(MIN(H91,AA91)-MIN(H91,(V91-MIN(C37,D91))/($B$91*24*$L$6)))*AB91)*IF(Q91<0,1+Q91/SUM(J91:P91),1) | G37: =((MIN(H91,(V91-MIN(C37,D91))/($B$91*24*$L$6))-MIN(MAX(H91-MIN(Supuestos!$C$27,IF(T91>0,$J$6/T91,0)),0),(V91-MIN(C37,D91))/($B$91*24*$L$6)))*AB91+D37*Z91-D37/Supuestos!$B$18*X91)*IF(Q91<0,1+Q91/SUM(J91:P91),1) | H37: =IF(Supuestos!$E$27="Sí",R91,0) | I37: =E37-J37 | J37: =F37+G37+H37 | K37: =J37/E37
A38: TOTAL | B38: =SUM(B26:B37) | C38: =SUM(C26:C37) | D38: =SUM(D26:D37) | E38: =SUM(E26:E37) | F38: =SUM(F26:F37) | G38: =SUM(G26:G37) | H38: =SUM(H26:H37) | I38: =SUM(I26:I37) | J38: =SUM(J26:J37) | K38: =J38/E38
A39: Factor anualización (12/meses): | B39: 1
A40: 4. PROYECCIÓN 20 AÑOS — Comprar vs PPA/Ahorro compartido
A41: Año | B41: Tarifa Actual $ | C41: Ah PV $ | D41: Ah BESS $ | E41: Ah FP $ | F41: Costo c/proy $ | G41: Flujo Compra $ | H41: Pago PPA $ | I41: Comisión $ | J41: Flujo Cliente PPA $ | K41: Flujo Financiador $ | L41: Acum Compra $ | M41: Acum Cliente PPA $
A42: 0 | G42: =-B22 | K42: =-B22 | L42: =G42 | M42: 0
A43: 1 | B43: =$E$38*$B$39*(1+Supuestos!$B$8)^1 | C43: =$F$38*$B$39*(1+Supuestos!$B$8)^1*((1-Supuestos!$B$11)*(1-Supuestos!$B$12)^0) | D43: =$G$38*$B$39*(1+Supuestos!$B$8)^1*(1-Supuestos!$B$13)^1*Supuestos!$B$10 | E43: =$H$38*$B$39*(1+Supuestos!$B$8)^1 | F43: =B43-C43-D43-E43 | G43: =C43+D43+E43-(IF(1<=Supuestos!$J$27,Supuestos!$B$19*Supuestos!$B$27*(1+Supuestos!$B$8)^0,0)+IF(1<=Supuestos!$B$22,Supuestos!$B$20*Supuestos!$D$27*(1+Supuestos!$B$8)^0,0)) | H43: =IF(1<=Supuestos!$J$27,$C$38*$B$39*((1-Supuestos!$B$11)*(1-Supuestos!$B$12)^0)*Supuestos!$I$27*(1+Supuestos!$B$9)^0,0) | I43: =IF(1<=Supuestos!$B$22,D43*Supuestos!$K$27,0) | J43: =C43+D43+E43-H43-I43 | K43: =H43+I43-(IF(1<=Supuestos!$J$27,Supuestos!$B$19*Supuestos!$B$27*(1+Supuestos!$B$8)^0,0)+IF(1<=Supuestos!$B$22,Supuestos!$B$20*Supuestos!$D$27*(1+Supuestos!$B$8)^0,0))-H43*Supuestos!$B$21 | L43: =L42+G43 | M43: =M42+J43
A44: 2 | B44: =$E$38*$B$39*(1+Supuestos!$B$8)^2 | C44: =$F$38*$B$39*(1+Supuestos!$B$8)^2*((1-Supuestos!$B$11)*(1-Supuestos!$B$12)^1) | D44: =$G$38*$B$39*(1+Supuestos!$B$8)^2*(1-Supuestos!$B$13)^2*Supuestos!$B$10 | E44: =$H$38*$B$39*(1+Supuestos!$B$8)^2 | F44: =B44-C44-D44-E44 | G44: =C44+D44+E44-(IF(2<=Supuestos!$J$27,Supuestos!$B$19*Supuestos!$B$27*(1+Supuestos!$B$8)^1,0)+IF(2<=Supuestos!$B$22,Supuestos!$B$20*Supuestos!$D$27*(1+Supuestos!$B$8)^1,0)) | H44: =IF(2<=Supuestos!$J$27,$C$38*$B$39*((1-Supuestos!$B$11)*(1-Supuestos!$B$12)^1)*Supuestos!$I$27*(1+Supuestos!$B$9)^1,0) | I44: =IF(2<=Supuestos!$B$22,D44*Supuestos!$K$27,0) | J44: =C44+D44+E44-H44-I44 | K44: =H44+I44-(IF(2<=Supuestos!$J$27,Supuestos!$B$19*Supuestos!$B$27*(1+Supuestos!$B$8)^1,0)+IF(2<=Supuestos!$B$22,Supuestos!$B$20*Supuestos!$D$27*(1+Supuestos!$B$8)^1,0))-H44*Supuestos!$B$21 | L44: =L43+G44 | M44: =M43+J44
...

Sheet Fiesta Americana Condesa Can
A1: Fiesta Americana Condesa Cancún — Memoria de cálculo y propuesta energética
A2: RPU 780881200029 · GDMTH SIN · Demanda contratada 5,115 kW · 12 meses de recibo
A3: Régimen: GENERADOR EXENTO — Medición Neta (sin permiso; Art. 30 LSE; RES/142/2017)
A5: PARÁMETROS (desde Supuestos — edítalos ahí)
A6: PV kWp | B6: =Supuestos!$B$28 | C6: BESS kW | D6: =Supuestos!$C$28 | E6: BESS kWh | F6: =Supuestos!$D$28 | G6: FP corrección | H6: =Supuestos!$E$28 | I6: Entrega útil kWh | J6: =Supuestos!$D$28*Supuestos!$B$17*SQRT(Supuestos!$B$18) | K6: FC umbral | L6: 0.57
A8: 1. ESTRUCTURA DE COSTO Y AHORRO (pre-IVA, año base · fórmulas vivas ← §3)
A9: Concepto | B9: $ / año | C9: Nota
A10: Tarifa Actual (CFE pleno, sin proyecto) | B10: =$E$38*$B$39 | C10: Σ recibos × anualización
A11: (−) Ahorro PV (energía + demanda) | B11: =$F$38*$B$39 | C11: intermedio + umbral
A12: (−) Ahorro BESS (punta + arbitraje) | B12: =$G$38*$B$39 | C12: recorte punta + arbitraje (incl. claw)
A13: (−) Ahorro FP (corrección) | B13: =$H$38*$B$39 | C13: multa factor de potencia
A14: (=) Costo neto con proyecto | B14: =B10-B11-B12-B13
A15: Ahorro proyecto / año | B15: =B11+B12+B13
A16: Ahorro % | B16: =B15/B10
A18: 2. CAPEX (fórmulas vivas desde Supuestos)
A19: CAPEX PV | B19: =Supuestos!$B$28*1000*Supuestos!$F$28*Supuestos!$B$5
A20: CAPEX BESS | B20: =Supuestos!$D$28*Supuestos!$G$28*Supuestos!$B$5
A21: CAPEX capacitor (FP) | B21: =Supuestos!$H$28
A22: CAPEX TOTAL | B22: =B19+B20+B21
A24: 3. RESUMEN MENSUAL — Tarifa Actual vs Con Proyecto (fórmulas vivas ← §6 y Supuestos)
A25: Mes | B25: kWh Consumo | C25: Gen PV kWh | D25: BESS desc kWh | E25: Tarifa Actual $ | F25: Ah PV $ | G25: Ah BESS $ | H25: Ah FP $ | I25: Costo c/proy $ | J25: Ahorro $ | K25: Ahorro %
A26: =A80 | B26: =V80 | C26: =Supuestos!$B$28*S80 | D26: =MIN($J$6*U80,E80) | E26: =SUM(J80:Q80) | F26: =(MIN(C26,D80)*Y80+(MIN(H80,AA80)-MIN(H80,(V80-MIN(C26,D80))/($B$80*24*$L$6)))*AB80)*IF(Q80<0,1+Q80/SUM(J80:P80),1) | G26: =((MIN(H80,(V80-MIN(C26,D80))/($B$80*24*$L$6))-MIN(MAX(H80-MIN(Supuestos!$C$28,IF(T80>0,$J$6/T80,0)),0),(V80-MIN(C26,D80))/($B$80*24*$L$6)))*AB80+D26*Z80-D26/Supuestos!$B$18*X80)*IF(Q80<0,1+Q80/SUM(J80:P80),1) | H26: =IF(Supuestos!$E$28="Sí",R80,0) | I26: =E26-J26 | J26: =F26+G26+H26 | K26: =J26/E26
A27: =A81 | B27: =V81 | C27: =Supuestos!$B$28*S81 | D27: =MIN($J$6*U81,E81) | E27: =SUM(J81:Q81) | F27: =(MIN(C27,D81)*Y81+(MIN(H81,AA81)-MIN(H81,(V81-MIN(C27,D81))/($B$81*24*$L$6)))*AB81)*IF(Q81<0,1+Q81/SUM(J81:P81),1) | G27: =((MIN(H81,(V81-MIN(C27,D81))/($B$81*24*$L$6))-MIN(MAX(H81-MIN(Supuestos!$C$28,IF(T81>0,$J$6/T81,0)),0),(V81-MIN(C27,D81))/($B$81*24*$L$6)))*AB81+D27*Z81-D27/Supuestos!$B$18*X81)*IF(Q81<0,1+Q81/SUM(J81:P81),1) | H27: =IF(Supuestos!$E$28="Sí",R81,0) | I27: =E27-J27 | J27: =F27+G27+H27 | K27: =J27/E27
A28: =A82 | B28: =V82 | C28: =Supuestos!$B$28*S82 | D28: =MIN($J$6*U82,E82) | E28: =SUM(J82:Q82) | F28: =(MIN(C28,D82)*Y82+(MIN(H82,AA82)-MIN(H82,(V82-MIN(C28,D82))/($B$82*24*$L$6)))*AB82)*IF(Q82<0,1+Q82/SUM(J82:P82),1) | G28: =((MIN(H82,(V82-MIN(C28,D82))/($B$82*24*$L$6))-MIN(MAX(H82-MIN(Supuestos!$C$28,IF(T82>0,$J$6/T82,0)),0),(V82-MIN(C28,D82))/($B$82*24*$L$6)))*AB82+D28*Z82-D28/Supuestos!$B$18*X82)*IF(Q82<0,1+Q82/SUM(J82:P82),1) | H28: =IF(Supuestos!$E$28="Sí",R82,0) | I28: =E28-J28 | J28: =F28+G28+H28 | K28: =J28/E28
A29: =A83 | B29: =V83 | C29: =Supuestos!$B$28*S83 | D29: =MIN($J$6*U83,E83) | E29: =SUM(J83:Q83) | F29: =(MIN(C29,D83)*Y83+(MIN(H83,AA83)-MIN(H83,(V83-MIN(C29,D83))/($B$83*24*$L$6)))*AB83)*IF(Q83<0,1+Q83/SUM(J83:P83),1) | G29: =((MIN(H83,(V83-MIN(C29,D83))/($B$83*24*$L$6))-MIN(MAX(H83-MIN(Supuestos!$C$28,IF(T83>0,$J$6/T83,0)),0),(V83-MIN(C29,D83))/($B$83*24*$L$6)))*AB83+D29*Z83-D29/Supuestos!$B$18*X83)*IF(Q83<0,1+Q83/SUM(J83:P83),1) | H29: =IF(Supuestos!$E$28="Sí",R83,0) | I29: =E29-J29 | J29: =F29+G29+H29 | K29: =J29/E29
A30: =A84 | B30: =V84 | C30: =Supuestos!$B$28*S84 | D30: =MIN($J$6*U84,E84) | E30: =SUM(J84:Q84) | F30: =(MIN(C30,D84)*Y84+(MIN(H84,AA84)-MIN(H84,(V84-MIN(C30,D84))/($B$84*24*$L$6)))*AB84)*IF(Q84<0,1+Q84/SUM(J84:P84),1) | G30: =((MIN(H84,(V84-MIN(C30,D84))/($B$84*24*$L$6))-MIN(MAX(H84-MIN(Supuestos!$C$28,IF(T84>0,$J$6/T84,0)),0),(V84-MIN(C30,D84))/($B$84*24*$L$6)))*AB84+D30*Z84-D30/Supuestos!$B$18*X84)*IF(Q84<0,1+Q84/SUM(J84:P84),1) | H30: =IF(Supuestos!$E$28="Sí",R84,0) | I30: =E30-J30 | J30: =F30+G30+H30 | K30: =J30/E30
A31: =A85 | B31: =V85 | C31: =Supuestos!$B$28*S85 | D31: =MIN($J$6*U85,E85) | E31: =SUM(J85:Q85) | F31: =(MIN(C31,D85)*Y85+(MIN(H85,AA85)-MIN(H85,(V85-MIN(C31,D85))/($B$85*24*$L$6)))*AB85)*IF(Q85<0,1+Q85/SUM(J85:P85),1) | G31: =((MIN(H85,(V85-MIN(C31,D85))/($B$85*24*$L$6))-MIN(MAX(H85-MIN(Supuestos!$C$28,IF(T85>0,$J$6/T85,0)),0),(V85-MIN(C31,D85))/($B$85*24*$L$6)))*AB85+D31*Z85-D31/Supuestos!$B$18*X85)*IF(Q85<0,1+Q85/SUM(J85:P85),1) | H31: =IF(Supuestos!$E$28="Sí",R85,0) | I31: =E31-J31 | J31: =F31+G31+H31 | K31: =J31/E31
A32: =A86 | B32: =V86 | C32: =Supuestos!$B$28*S86 | D32: =MIN($J$6*U86,E86) | E32: =SUM(J86:Q86) | F32: =(MIN(C32,D86)*Y86+(MIN(H86,AA86)-MIN(H86,(V86-MIN(C32,D86))/($B$86*24*$L$6)))*AB86)*IF(Q86<0,1+Q86/SUM(J86:P86),1) | G32: =((MIN(H86,(V86-MIN(C32,D86))/($B$86*24*$L$6))-MIN(MAX(H86-MIN(Supuestos!$C$28,IF(T86>0,$J$6/T86,0)),0),(V86-MIN(C32,D86))/($B$86*24*$L$6)))*AB86+D32*Z86-D32/Supuestos!$B$18*X86)*IF(Q86<0,1+Q86/SUM(J86:P86),1) | H32: =IF(Supuestos!$E$28="Sí",R86,0) | I32: =E32-J32 | J32: =F32+G32+H32 | K32: =J32/E32
A33: =A87 | B33: =V87 | C33: =Supuestos!$B$28*S87 | D33: =MIN($J$6*U87,E87) | E33: =SUM(J87:Q87) | F33: =(MIN(C33,D87)*Y87+(MIN(H87,AA87)-MIN(H87,(V87-MIN(C33,D87))/($B$87*24*$L$6)))*AB87)*IF(Q87<0,1+Q87/SUM(J87:P87),1) | G33: =((MIN(H87,(V87-MIN(C33,D87))/($B$87*24*$L$6))-MIN(MAX(H87-MIN(Supuestos!$C$28,IF(T87>0,$J$6/T87,0)),0),(V87-MIN(C33,D87))/($B$87*24*$L$6)))*AB87+D33*Z87-D33/Supuestos!$B$18*X87)*IF(Q87<0,1+Q87/SUM(J87:P87),1) | H33: =IF(Supuestos!$E$28="Sí",R87,0) | I33: =E33-J33 | J33: =F33+G33+H33 | K33: =J33/E33
A34: =A88 | B34: =V88 | C34: =Supuestos!$B$28*S88 | D34: =MIN($J$6*U88,E88) | E34: =SUM(J88:Q88) | F34: =(MIN(C34,D88)*Y88+(MIN(H88,AA88)-MIN(H88,(V88-MIN(C34,D88))/($B$88*24*$L$6)))*AB88)*IF(Q88<0,1+Q88/SUM(J88:P88),1) | G34: =((MIN(H88,(V88-MIN(C34,D88))/($B$88*24*$L$6))-MIN(MAX(H88-MIN(Supuestos!$C$28,IF(T88>0,$J$6/T88,0)),0),(V88-MIN(C34,D88))/($B$88*24*$L$6)))*AB88+D34*Z88-D34/Supuestos!$B$18*X88)*IF(Q88<0,1+Q88/SUM(J88:P88),1) | H34: =IF(Supuestos!$E$28="Sí",R88,0) | I34: =E34-J34 | J34: =F34+G34+H34 | K34: =J34/E34
A35: =A89 | B35: =V89 | C35: =Supuestos!$B$28*S89 | D35: =MIN($J$6*U89,E89) | E35: =SUM(J89:Q89) | F35: =(MIN(C35,D89)*Y89+(MIN(H89,AA89)-MIN(H89,(V89-MIN(C35,D89))/($B$89*24*$L$6)))*AB89)*IF(Q89<0,1+Q89/SUM(J89:P89),1) | G35: =((MIN(H89,(V89-MIN(C35,D89))/($B$89*24*$L$6))-MIN(MAX(H89-MIN(Supuestos!$C$28,IF(T89>0,$J$6/T89,0)),0),(V89-MIN(C35,D89))/($B$89*24*$L$6)))*AB89+D35*Z89-D35/Supuestos!$B$18*X89)*IF(Q89<0,1+Q89/SUM(J89:P89),1) | H35: =IF(Supuestos!$E$28="Sí",R89,0) | I35: =E35-J35 | J35: =F35+G35+H35 | K35: =J35/E35
A36: =A90 | B36: =V90 | C36: =Supuestos!$B$28*S90 | D36: =MIN($J$6*U90,E90) | E36: =SUM(J90:Q90) | F36: =(MIN(C36,D90)*Y90+(MIN(H90,AA90)-MIN(H90,(V90-MIN(C36,D90))/($B$90*24*$L$6)))*AB90)*IF(Q90<0,1+Q90/SUM(J90:P90),1) | G36: =((MIN(H90,(V90-MIN(C36,D90))/($B$90*24*$L$6))-MIN(MAX(H90-MIN(Supuestos!$C$28,IF(T90>0,$J$6/T90,0)),0),(V90-MIN(C36,D90))/($B$90*24*$L$6)))*AB90+D36*Z90-D36/Supuestos!$B$18*X90)*IF(Q90<0,1+Q90/SUM(J90:P90),1) | H36: =IF(Supuestos!$E$28="Sí",R90,0) | I36: =E36-J36 | J36: =F36+G36+H36 | K36: =J36/E36
A37: =A91 | B37: =V91 | C37: =Supuestos!$B$28*S91 | D37: =MIN($J$6*U91,E91) | E37: =SUM(J91:Q91) | F37: =(MIN(C37,D91)*Y91+(MIN(H91,AA91)-MIN(H91,(V91-MIN(C37,D91))/($B$91*24*$L$6)))*AB91)*IF(Q91<0,1+Q91/SUM(J91:P91),1) | G37: =((MIN(H91,(V91-MIN(C37,D91))/($B$91*24*$L$6))-MIN(MAX(H91-MIN(Supuestos!$C$28,IF(T91>0,$J$6/T91,0)),0),(V91-MIN(C37,D91))/($B$91*24*$L$6)))*AB91+D37*Z91-D37/Supuestos!$B$18*X91)*IF(Q91<0,1+Q91/SUM(J91:P91),1) | H37: =IF(Supuestos!$E$28="Sí",R91,0) | I37: =E37-J37 | J37: =F37+G37+H37 | K37: =J37/E37
A38: TOTAL | B38: =SUM(B26:B37) | C38: =SUM(C26:C37) | D38: =SUM(D26:D37) | E38: =SUM(E26:E37) | F38: =SUM(F26:F37) | G38: =SUM(G26:G37) | H38: =SUM(H26:H37) | I38: =SUM(I26:I37) | J38: =SUM(J26:J37) | K38: =J38/E38
A39: Factor anualización (12/meses): | B39: 1
A40: 4. PROYECCIÓN 20 AÑOS — Comprar vs PPA/Ahorro compartido
A41: Año | B41: Tarifa Actual $ | C41: Ah PV $ | D41: Ah BESS $ | E41: Ah FP $ | F41: Costo c/proy $ | G41: Flujo Compra $ | H41: Pago PPA $ | I41: Comisión $ | J41: Flujo Cliente PPA $ | K41: Flujo Financiador $ | L41: Acum Compra $ | M41: Acum Cliente PPA $
A42: 0 | G42: =-B22 | K42: =-B22 | L42: =G42 | M42: 0
A43: 1 | B43: =$E$38*$B$39*(1+Supuestos!$B$8)^1 | C43: =$F$38*$B$39*(1+Supuestos!$B$8)^1*((1-Supuestos!$B$11)*(1-Supuestos!$B$12)^0) | D43: =$G$38*$B$39*(1+Supuestos!$B$8)^1*(1-Supuestos!$B$13)^1*Supuestos!$B$10 | E43: =$H$38*$B$39*(1+Supuestos!$B$8)^1 | F43: =B43-C43-D43-E43 | G43: =C43+D43+E43-(IF(1<=Supuestos!$J$28,Supuestos!$B$19*Supuestos!$B$28*(1+Supuestos!$B$8)^0,0)+IF(1<=Supuestos!$B$22,Supuestos!$B$20*Supuestos!$D$28*(1+Supuestos!$B$8)^0,0)) | H43: =IF(1<=Supuestos!$J$28,$C$38*$B$39*((1-Supuestos!$B$11)*(1-Supuestos!$B$12)^0)*Supuestos!$I$28*(1+Supuestos!$B$9)^0,0) | I43: =IF(1<=Supuestos!$B$22,D43*Supuestos!$K$28,0) | J43: =C43+D43+E43-H43-I43 | K43: =H43+I43-(IF(1<=Supuestos!$J$28,Supuestos!$B$19*Supuestos!$B$28*(1+Supuestos!$B$8)^0,0)+IF(1<=Supuestos!$B$22,Supuestos!$B$20*Supuestos!$D$28*(1+Supuestos!$B$8)^0,0))-H43*Supuestos!$B$21 | L43: =L42+G43 | M43: =M42+J43
A44: 2 | B44: =$E$38*$B$39*(1+Supuestos!$B$8)^2 | C44: =$F$38*$B$39*(1+Supuestos!$B$8)^2*((1-Supuestos!$B$11)*(1-Supuestos!$B$12)^1) | D44: =$G$38*$B$39*(1+Supuestos!$B$8)^2*(1-Supuestos!$B$13)^2*Supuestos!$B$10 | E44: =$H$38*$B$39*(1+Supuestos!$B$8)^2 | F44: =B44-C44-D44-E44 | G44: =C44+D44+E44-(IF(2<=Supuestos!$J$28,Supuestos!$B$19*Supuestos!$B$28*(1+Supuestos!$B$8)^1,0)+IF(2<=Supuestos!$B$22,Supuestos!$B$20*Supuestos!$D$28*(1+Supuestos!$B$8)^1,0)) | H44: =IF(2<=Supuestos!$J$28,$C$38*$B$39*((1-Supuestos!$B$11)*(1-Supuestos!$B$12)^1)*Supuestos!$I$28*(1+Supuestos!$B$9)^1,0) | I44: =IF(2<=Supuestos!$B$22,D44*Supuestos!$K$28,0) | J44: =C44+D44+E44-H44-I44 | K44: =H44+I44-(IF(2<=Supuestos!$J$28,Supuestos!$B$19*Supuestos!$B$28*(1+Supuestos!$B$8)^1,0)+IF(2<=Supuestos!$B$22,Supuestos!$B$20*Supuestos!$D$28*(1+Supuestos!$B$8)^1,0))-H44*Supuestos!$B$21 | L44: =L43+G44 | M44: =M43+J44
...

Sheet Fiesta Inn Periférico Sur (C
A1: Fiesta Inn Periférico Sur (CDMX) — Memoria de cálculo y propuesta energética
A2: RPU 968221200700 · GDMTH SIN · Demanda contratada 366 kW · 12 meses de recibo
A3: Régimen: GENERADOR EXENTO — Medición Neta (sin permiso; Art. 30 LSE; RES/142/2017)
A5: PARÁMETROS (desde Supuestos — edítalos ahí)
A6: PV kWp | B6: =Supuestos!$B$29 | C6: BESS kW | D6: =Supuestos!$C$29 | E6: BESS kWh | F6: =Supuestos!$D$29 | G6: FP corrección | H6: =Supuestos!$E$29 | I6: Entrega útil kWh | J6: =Supuestos!$D$29*Supuestos!$B$17*SQRT(Supuestos!$B$18) | K6: FC umbral | L6: 0.57
A8: 1. ESTRUCTURA DE COSTO Y AHORRO (pre-IVA, año base · fórmulas vivas ← §3)
A9: Concepto | B9: $ / año | C9: Nota
A10: Tarifa Actual (CFE pleno, sin proyecto) | B10: =$E$38*$B$39 | C10: Σ recibos × anualización
A11: (−) Ahorro PV (energía + demanda) | B11: =$F$38*$B$39 | C11: intermedio + umbral
A12: (−) Ahorro BESS (punta + arbitraje) | B12: =$G$38*$B$39 | C12: recorte punta + arbitraje (incl. claw)
A13: (−) Ahorro FP (corrección) | B13: =$H$38*$B$39 | C13: multa factor de potencia
A14: (=) Costo neto con proyecto | B14: =B10-B11-B12-B13
A15: Ahorro proyecto / año | B15: =B11+B12+B13
A16: Ahorro % | B16: =B15/B10
A18: 2. CAPEX (fórmulas vivas desde Supuestos)
A19: CAPEX PV | B19: =Supuestos!$B$29*1000*Supuestos!$F$29*Supuestos!$B$5
A20: CAPEX BESS | B20: =Supuestos!$D$29*Supuestos!$G$29*Supuestos!$B$5
A21: CAPEX capacitor (FP) | B21: =Supuestos!$H$29
A22: CAPEX TOTAL | B22: =B19+B20+B21
A24: 3. RESUMEN MENSUAL — Tarifa Actual vs Con Proyecto (fórmulas vivas ← §6 y Supuestos)
A25: Mes | B25: kWh Consumo | C25: Gen PV kWh | D25: BESS desc kWh | E25: Tarifa Actual $ | F25: Ah PV $ | G25: Ah BESS $ | H25: Ah FP $ | I25: Costo c/proy $ | J25: Ahorro $ | K25: Ahorro %
A26: =A80 | B26: =V80 | C26: =Supuestos!$B$29*S80 | D26: =MIN($J$6*U80,E80) | E26: =SUM(J80:Q80) | F26: =(MIN(C26,D80)*Y80+(MIN(H80,AA80)-MIN(H80,(V80-MIN(C26,D80))/($B$80*24*$L$6)))*AB80)*IF(Q80<0,1+Q80/SUM(J80:P80),1) | G26: =((MIN(H80,(V80-MIN(C26,D80))/($B$80*24*$L$6))-MIN(MAX(H80-MIN(Supuestos!$C$29,IF(T80>0,$J$6/T80,0)),0),(V80-MIN(C26,D80))/($B$80*24*$L$6)))*AB80+D26*Z80-D26/Supuestos!$B$18*X80)*IF(Q80<0,1+Q80/SUM(J80:P80),1) | H26: =IF(Supuestos!$E$29="Sí",R80,0) | I26: =E26-J26 | J26: =F26+G26+H26 | K26: =J26/E26
A27: =A81 | B27: =V81 | C27: =Supuestos!$B$29*S81 | D27: =MIN($J$6*U81,E81) | E27: =SUM(J81:Q81) | F27: =(MIN(C27,D81)*Y81+(MIN(H81,AA81)-MIN(H81,(V81-MIN(C27,D81))/($B$81*24*$L$6)))*AB81)*IF(Q81<0,1+Q81/SUM(J81:P81),1) | G27: =((MIN(H81,(V81-MIN(C27,D81))/($B$81*24*$L$6))-MIN(MAX(H81-MIN(Supuestos!$C$29,IF(T81>0,$J$6/T81,0)),0),(V81-MIN(C27,D81))/($B$81*24*$L$6)))*AB81+D27*Z81-D27/Supuestos!$B$18*X81)*IF(Q81<0,1+Q81/SUM(J81:P81),1) | H27: =IF(Supuestos!$E$29="Sí",R81,0) | I27: =E27-J27 | J27: =F27+G27+H27 | K27: =J27/E27
A28: =A82 | B28: =V82 | C28: =Supuestos!$B$29*S82 | D28: =MIN($J$6*U82,E82) | E28: =SUM(J82:Q82) | F28: =(MIN(C28,D82)*Y82+(MIN(H82,AA82)-MIN(H82,(V82-MIN(C28,D82))/($B$82*24*$L$6)))*AB82)*IF(Q82<0,1+Q82/SUM(J82:P82),1) | G28: =((MIN(H82,(V82-MIN(C28,D82))/($B$82*24*$L$6))-MIN(MAX(H82-MIN(Supuestos!$C$29,IF(T82>0,$J$6/T82,0)),0),(V82-MIN(C28,D82))/($B$82*24*$L$6)))*AB82+D28*Z82-D28/Supuestos!$B$18*X82)*IF(Q82<0,1+Q82/SUM(J82:P82),1) | H28: =IF(Supuestos!$E$29="Sí",R82,0) | I28: =E28-J28 | J28: =F28+G28+H28 | K28: =J28/E28
A29: =A83 | B29: =V83 | C29: =Supuestos!$B$29*S83 | D29: =MIN($J$6*U83,E83) | E29: =SUM(J83:Q83) | F29: =(MIN(C29,D83)*Y83+(MIN(H83,AA83)-MIN(H83,(V83-MIN(C29,D83))/($B$83*24*$L$6)))*AB83)*IF(Q83<0,1+Q83/SUM(J83:P83),1) | G29: =((MIN(H83,(V83-MIN(C29,D83))/($B$83*24*$L$6))-MIN(MAX(H83-MIN(Supuestos!$C$29,IF(T83>0,$J$6/T83,0)),0),(V83-MIN(C29,D83))/($B$83*24*$L$6)))*AB83+D29*Z83-D29/Supuestos!$B$18*X83)*IF(Q83<0,1+Q83/SUM(J83:P83),1) | H29: =IF(Supuestos!$E$29="Sí",R83,0) | I29: =E29-J29 | J29: =F29+G29+H29 | K29: =J29/E29
A30: =A84 | B30: =V84 | C30: =Supuestos!$B$29*S84 | D30: =MIN($J$6*U84,E84) | E30: =SUM(J84:Q84) | F30: =(MIN(C30,D84)*Y84+(MIN(H84,AA84)-MIN(H84,(V84-MIN(C30,D84))/($B$84*24*$L$6)))*AB84)*IF(Q84<0,1+Q84/SUM(J84:P84),1) | G30: =((MIN(H84,(V84-MIN(C30,D84))/($B$84*24*$L$6))-MIN(MAX(H84-MIN(Supuestos!$C$29,IF(T84>0,$J$6/T84,0)),0),(V84-MIN(C30,D84))/($B$84*24*$L$6)))*AB84+D30*Z84-D30/Supuestos!$B$18*X84)*IF(Q84<0,1+Q84/SUM(J84:P84),1) | H30: =IF(Supuestos!$E$29="Sí",R84,0) | I30: =E30-J30 | J30: =F30+G30+H30 | K30: =J30/E30
A31: =A85 | B31: =V85 | C31: =Supuestos!$B$29*S85 | D31: =MIN($J$6*U85,E85) | E31: =SUM(J85:Q85) | F31: =(MIN(C31,D85)*Y85+(MIN(H85,AA85)-MIN(H85,(V85-MIN(C31,D85))/($B$85*24*$L$6)))*AB85)*IF(Q85<0,1+Q85/SUM(J85:P85),1) | G31: =((MIN(H85,(V85-MIN(C31,D85))/($B$85*24*$L$6))-MIN(MAX(H85-MIN(Supuestos!$C$29,IF(T85>0,$J$6/T85,0)),0),(V85-MIN(C31,D85))/($B$85*24*$L$6)))*AB85+D31*Z85-D31/Supuestos!$B$18*X85)*IF(Q85<0,1+Q85/SUM(J85:P85),1) | H31: =IF(Supuestos!$E$29="Sí",R85,0) | I31: =E31-J31 | J31: =F31+G31+H31 | K31: =J31/E31
A32: =A86 | B32: =V86 | C32: =Supuestos!$B$29*S86 | D32: =MIN($J$6*U86,E86) | E32: =SUM(J86:Q86) | F32: =(MIN(C32,D86)*Y86+(MIN(H86,AA86)-MIN(H86,(V86-MIN(C32,D86))/($B$86*24*$L$6)))*AB86)*IF(Q86<0,1+Q86/SUM(J86:P86),1) | G32: =((MIN(H86,(V86-MIN(C32,D86))/($B$86*24*$L$6))-MIN(MAX(H86-MIN(Supuestos!$C$29,IF(T86>0,$J$6/T86,0)),0),(V86-MIN(C32,D86))/($B$86*24*$L$6)))*AB86+D32*Z86-D32/Supuestos!$B$18*X86)*IF(Q86<0,1+Q86/SUM(J86:P86),1) | H32: =IF(Supuestos!$E$29="Sí",R86,0) | I32: =E32-J32 | J32: =F32+G32+H32 | K32: =J32/E32
A33: =A87 | B33: =V87 | C33: =Supuestos!$B$29*S87 | D33: =MIN($J$6*U87,E87) | E33: =SUM(J87:Q87) | F33: =(MIN(C33,D87)*Y87+(MIN(H87,AA87)-MIN(H87,(V87-MIN(C33,D87))/($B$87*24*$L$6)))*AB87)*IF(Q87<0,1+Q87/SUM(J87:P87),1) | G33: =((MIN(H87,(V87-MIN(C33,D87))/($B$87*24*$L$6))-MIN(MAX(H87-MIN(Supuestos!$C$29,IF(T87>0,$J$6/T87,0)),0),(V87-MIN(C33,D87))/($B$87*24*$L$6)))*AB87+D33*Z87-D33/Supuestos!$B$18*X87)*IF(Q87<0,1+Q87/SUM(J87:P87),1) | H33: =IF(Supuestos!$E$29="Sí",R87,0) | I33: =E33-J33 | J33: =F33+G33+H33 | K33: =J33/E33
A34: =A88 | B34: =V88 | C34: =Supuestos!$B$29*S88 | D34: =MIN($J$6*U88,E88) | E34: =SUM(J88:Q88) | F34: =(MIN(C34,D88)*Y88+(MIN(H88,AA88)-MIN(H88,(V88-MIN(C34,D88))/($B$88*24*$L$6)))*AB88)*IF(Q88<0,1+Q88/SUM(J88:P88),1) | G34: =((MIN(H88,(V88-MIN(C34,D88))/($B$88*24*$L$6))-MIN(MAX(H88-MIN(Supuestos!$C$29,IF(T88>0,$J$6/T88,0)),0),(V88-MIN(C34,D88))/($B$88*24*$L$6)))*AB88+D34*Z88-D34/Supuestos!$B$18*X88)*IF(Q88<0,1+Q88/SUM(J88:P88),1) | H34: =IF(Supuestos!$E$29="Sí",R88,0) | I34: =E34-J34 | J34: =F34+G34+H34 | K34: =J34/E34
A35: =A89 | B35: =V89 | C35: =Supuestos!$B$29*S89 | D35: =MIN($J$6*U89,E89) | E35: =SUM(J89:Q89) | F35: =(MIN(C35,D89)*Y89+(MIN(H89,AA89)-MIN(H89,(V89-MIN(C35,D89))/($B$89*24*$L$6)))*AB89)*IF(Q89<0,1+Q89/SUM(J89:P89),1) | G35: =((MIN(H89,(V89-MIN(C35,D89))/($B$89*24*$L$6))-MIN(MAX(H89-MIN(Supuestos!$C$29,IF(T89>0,$J$6/T89,0)),0),(V89-MIN(C35,D89))/($B$89*24*$L$6)))*AB89+D35*Z89-D35/Supuestos!$B$18*X89)*IF(Q89<0,1+Q89/SUM(J89:P89),1) | H35: =IF(Supuestos!$E$29="Sí",R89,0) | I35: =E35-J35 | J35: =F35+G35+H35 | K35: =J35/E35
A36: =A90 | B36: =V90 | C36: =Supuestos!$B$29*S90 | D36: =MIN($J$6*U90,E90) | E36: =SUM(J90:Q90) | F36: =(MIN(C36,D90)*Y90+(MIN(H90,AA90)-MIN(H90,(V90-MIN(C36,D90))/($B$90*24*$L$6)))*AB90)*IF(Q90<0,1+Q90/SUM(J90:P90),1) | G36: =((MIN(H90,(V90-MIN(C36,D90))/($B$90*24*$L$6))-MIN(MAX(H90-MIN(Supuestos!$C$29,IF(T90>0,$J$6/T90,0)),0),(V90-MIN(C36,D90))/($B$90*24*$L$6)))*AB90+D36*Z90-D36/Supuestos!$B$18*X90)*IF(Q90<0,1+Q90/SUM(J90:P90),1) | H36: =IF(Supuestos!$E$29="Sí",R90,0) | I36: =E36-J36 | J36: =F36+G36+H36 | K36: =J36/E36
A37: =A91 | B37: =V91 | C37: =Supuestos!$B$29*S91 | D37: =MIN($J$6*U91,E91) | E37: =SUM(J91:Q91) | F37: =(MIN(C37,D91)*Y91+(MIN(H91,AA91)-MIN(H91,(V91-MIN(C37,D91))/($B$91*24*$L$6)))*AB91)*IF(Q91<0,1+Q91/SUM(J91:P91),1) | G37: =((MIN(H91,(V91-MIN(C37,D91))/($B$91*24*$L$6))-MIN(MAX(H91-MIN(Supuestos!$C$29,IF(T91>0,$J$6/T91,0)),0),(V91-MIN(C37,D91))/($B$91*24*$L$6)))*AB91+D37*Z91-D37/Supuestos!$B$18*X91)*IF(Q91<0,1+Q91/SUM(J91:P91),1) | H37: =IF(Supuestos!$E$29="Sí",R91,0) | I37: =E37-J37 | J37: =F37+G37+H37 | K37: =J37/E37
A38: TOTAL | B38: =SUM(B26:B37) | C38: =SUM(C26:C37) | D38: =SUM(D26:D37) | E38: =SUM(E26:E37) | F38: =SUM(F26:F37) | G38: =SUM(G26:G37) | H38: =SUM(H26:H37) | I38: =SUM(I26:I37) | J38: =SUM(J26:J37) | K38: =J38/E38
A39: Factor anualización (12/meses): | B39: 1
A40: 4. PROYECCIÓN 20 AÑOS — Comprar vs PPA/Ahorro compartido
A41: Año | B41: Tarifa Actual $ | C41: Ah PV $ | D41: Ah BESS $ | E41: Ah FP $ | F41: Costo c/proy $ | G41: Flujo Compra $ | H41: Pago PPA $ | I41: Comisión $ | J41: Flujo Cliente PPA $ | K41: Flujo Financiador $ | L41: Acum Compra $ | M41: Acum Cliente PPA $
A42: 0 | G42: =-B22 | K42: =-B22 | L42: =G42 | M42: 0
A43: 1 | B43: =$E$38*$B$39*(1+Supuestos!$B$8)^1 | C43: =$F$38*$B$39*(1+Supuestos!$B$8)^1*((1-Supuestos!$B$11)*(1-Supuestos!$B$12)^0) | D43: =$G$38*$B$39*(1+Supuestos!$B$8)^1*(1-Supuestos!$B$13)^1*Supuestos!$B$10 | E43: =$H$38*$B$39*(1+Supuestos!$B$8)^1 | F43: =B43-C43-D43-E43 | G43: =C43+D43+E43-(IF(1<=Supuestos!$J$29,Supuestos!$B$19*Supuestos!$B$29*(1+Supuestos!$B$8)^0,0)+IF(1<=Supuestos!$B$22,Supuestos!$B$20*Supuestos!$D$29*(1+Supuestos!$B$8)^0,0)) | H43: =IF(1<=Supuestos!$J$29,$C$38*$B$39*((1-Supuestos!$B$11)*(1-Supuestos!$B$12)^0)*Supuestos!$I$29*(1+Supuestos!$B$9)^0,0) | I43: =IF(1<=Supuestos!$B$22,D43*Supuestos!$K$29,0) | J43: =C43+D43+E43-H43-I43 | K43: =H43+I43-(IF(1<=Supuestos!$J$29,Supuestos!$B$19*Supuestos!$B$29*(1+Supuestos!$B$8)^0,0)+IF(1<=Supuestos!$B$22,Supuestos!$B$20*Supuestos!$D$29*(1+Supuestos!$B$8)^0,0))-H43*Supuestos!$B$21 | L43: =L42+G43 | M43: =M42+J43
A44: 2 | B44: =$E$38*$B$39*(1+Supuestos!$B$8)^2 | C44: =$F$38*$B$39*(1+Supuestos!$B$8)^2*((1-Supuestos!$B$11)*(1-Supuestos!$B$12)^1) | D44: =$G$38*$B$39*(1+Supuestos!$B$8)^2*(1-Supuestos!$B$13)^2*Supuestos!$B$10 | E44: =$H$38*$B$39*(1+Supuestos!$B$8)^2 | F44: =B44-C44-D44-E44 | G44: =C44+D44+E44-(IF(2<=Supuestos!$J$29,Supuestos!$B$19*Supuestos!$B$29*(1+Supuestos!$B$8)^1,0)+IF(2<=Supuestos!$B$22,Supuestos!$B$20*Supuestos!$D$29*(1+Supuestos!$B$8)^1,0)) | H44: =IF(2<=Supuestos!$J$29,$C$38*$B$39*((1-Supuestos!$B$11)*(1-Supuestos!$B$12)^1)*Supuestos!$I$29*(1+Supuestos!$B$9)^1,0) | I44: =IF(2<=Supuestos!$B$22,D44*Supuestos!$K$29,0) | J44: =C44+D44+E44-H44-I44 | K44: =H44+I44-(IF(2<=Supuestos!$J$29,Supuestos!$B$19*Supuestos!$B$29*(1+Supuestos!$B$8)^1,0)+IF(2<=Supuestos!$B$22,Supuestos!$B$20*Supuestos!$D$29*(1+Supuestos!$B$8)^1,0))-H44*Supuestos!$B$21 | L44: =L43+G44 | M44: =M43+J44
...

Sheet Fiesta Americana Viaducto Ae
A1: Fiesta Americana Viaducto Aeropuerto (CDMX) — Memoria de cálculo y propuesta energética
A2: RPU 986190901451 · GDMTH SIN · Demanda contratada 820 kW · 12 meses de recibo
A3: Régimen: GENERADOR EXENTO — Medición Neta (sin permiso; Art. 30 LSE; RES/142/2017)
A5: PARÁMETROS (desde Supuestos — edítalos ahí)
A6: PV kWp | B6: =Supuestos!$B$30 | C6: BESS kW | D6: =Supuestos!$C$30 | E6: BESS kWh | F6: =Supuestos!$D$30 | G6: FP corrección | H6: =Supuestos!$E$30 | I6: Entrega útil kWh | J6: =Supuestos!$D$30*Supuestos!$B$17*SQRT(Supuestos!$B$18) | K6: FC umbral | L6: 0.57
A8: 1. ESTRUCTURA DE COSTO Y AHORRO (pre-IVA, año base · fórmulas vivas ← §3)
A9: Concepto | B9: $ / año | C9: Nota
A10: Tarifa Actual (CFE pleno, sin proyecto) | B10: =$E$38*$B$39 | C10: Σ recibos × anualización
A11: (−) Ahorro PV (energía + demanda) | B11: =$F$38*$B$39 | C11: intermedio + umbral
A12: (−) Ahorro BESS (punta + arbitraje) | B12: =$G$38*$B$39 | C12: recorte punta + arbitraje (incl. claw)
A13: (−) Ahorro FP (corrección) | B13: =$H$38*$B$39 | C13: multa factor de potencia
A14: (=) Costo neto con proyecto | B14: =B10-B11-B12-B13
A15: Ahorro proyecto / año | B15: =B11+B12+B13
A16: Ahorro % | B16: =B15/B10
A18: 2. CAPEX (fórmulas vivas desde Supuestos)
A19: CAPEX PV | B19: =Supuestos!$B$30*1000*Supuestos!$F$30*Supuestos!$B$5
A20: CAPEX BESS | B20: =Supuestos!$D$30*Supuestos!$G$30*Supuestos!$B$5
A21: CAPEX capacitor (FP) | B21: =Supuestos!$H$30
A22: CAPEX TOTAL | B22: =B19+B20+B21
A24: 3. RESUMEN MENSUAL — Tarifa Actual vs Con Proyecto (fórmulas vivas ← §6 y Supuestos)
A25: Mes | B25: kWh Consumo | C25: Gen PV kWh | D25: BESS desc kWh | E25: Tarifa Actual $ | F25: Ah PV $ | G25: Ah BESS $ | H25: Ah FP $ | I25: Costo c/proy $ | J25: Ahorro $ | K25: Ahorro %
A26: =A80 | B26: =V80 | C26: =Supuestos!$B$30*S80 | D26: =MIN($J$6*U80,E80) | E26: =SUM(J80:Q80) | F26: =(MIN(C26,D80)*Y80+(MIN(H80,AA80)-MIN(H80,(V80-MIN(C26,D80))/($B$80*24*$L$6)))*AB80)*IF(Q80<0,1+Q80/SUM(J80:P80),1) | G26: =((MIN(H80,(V80-MIN(C26,D80))/($B$80*24*$L$6))-MIN(MAX(H80-MIN(Supuestos!$C$30,IF(T80>0,$J$6/T80,0)),0),(V80-MIN(C26,D80))/($B$80*24*$L$6)))*AB80+D26*Z80-D26/Supuestos!$B$18*X80)*IF(Q80<0,1+Q80/SUM(J80:P80),1) | H26: =IF(Supuestos!$E$30="Sí",R80,0) | I26: =E26-J26 | J26: =F26+G26+H26 | K26: =J26/E26
A27: =A81 | B27: =V81 | C27: =Supuestos!$B$30*S81 | D27: =MIN($J$6*U81,E81) | E27: =SUM(J81:Q81) | F27: =(MIN(C27,D81)*Y81+(MIN(H81,AA81)-MIN(H81,(V81-MIN(C27,D81))/($B$81*24*$L$6)))*AB81)*IF(Q81<0,1+Q81/SUM(J81:P81),1) | G27: =((MIN(H81,(V81-MIN(C27,D81))/($B$81*24*$L$6))-MIN(MAX(H81-MIN(Supuestos!$C$30,IF(T81>0,$J$6/T81,0)),0),(V81-MIN(C27,D81))/($B$81*24*$L$6)))*AB81+D27*Z81-D27/Supuestos!$B$18*X81)*IF(Q81<0,1+Q81/SUM(J81:P81),1) | H27: =IF(Supuestos!$E$30="Sí",R81,0) | I27: =E27-J27 | J27: =F27+G27+H27 | K27: =J27/E27
A28: =A82 | B28: =V82 | C28: =Supuestos!$B$30*S82 | D28: =MIN($J$6*U82,E82) | E28: =SUM(J82:Q82) | F28: =(MIN(C28,D82)*Y82+(MIN(H82,AA82)-MIN(H82,(V82-MIN(C28,D82))/($B$82*24*$L$6)))*AB82)*IF(Q82<0,1+Q82/SUM(J82:P82),1) | G28: =((MIN(H82,(V82-MIN(C28,D82))/($B$82*24*$L$6))-MIN(MAX(H82-MIN(Supuestos!$C$30,IF(T82>0,$J$6/T82,0)),0),(V82-MIN(C28,D82))/($B$82*24*$L$6)))*AB82+D28*Z82-D28/Supuestos!$B$18*X82)*IF(Q82<0,1+Q82/SUM(J82:P82),1) | H28: =IF(Supuestos!$E$30="Sí",R82,0) | I28: =E28-J28 | J28: =F28+G28+H28 | K28: =J28/E28
A29: =A83 | B29: =V83 | C29: =Supuestos!$B$30*S83 | D29: =MIN($J$6*U83,E83) | E29: =SUM(J83:Q83) | F29: =(MIN(C29,D83)*Y83+(MIN(H83,AA83)-MIN(H83,(V83-MIN(C29,D83))/($B$83*24*$L$6)))*AB83)*IF(Q83<0,1+Q83/SUM(J83:P83),1) | G29: =((MIN(H83,(V83-MIN(C29,D83))/($B$83*24*$L$6))-MIN(MAX(H83-MIN(Supuestos!$C$30,IF(T83>0,$J$6/T83,0)),0),(V83-MIN(C29,D83))/($B$83*24*$L$6)))*AB83+D29*Z83-D29/Supuestos!$B$18*X83)*IF(Q83<0,1+Q83/SUM(J83:P83),1) | H29: =IF(Supuestos!$E$30="Sí",R83,0) | I29: =E29-J29 | J29: =F29+G29+H29 | K29: =J29/E29
A30: =A84 | B30: =V84 | C30: =Supuestos!$B$30*S84 | D30: =MIN($J$6*U84,E84) | E30: =SUM(J84:Q84) | F30: =(MIN(C30,D84)*Y84+(MIN(H84,AA84)-MIN(H84,(V84-MIN(C30,D84))/($B$84*24*$L$6)))*AB84)*IF(Q84<0,1+Q84/SUM(J84:P84),1) | G30: =((MIN(H84,(V84-MIN(C30,D84))/($B$84*24*$L$6))-MIN(MAX(H84-MIN(Supuestos!$C$30,IF(T84>0,$J$6/T84,0)),0),(V84-MIN(C30,D84))/($B$84*24*$L$6)))*AB84+D30*Z84-D30/Supuestos!$B$18*X84)*IF(Q84<0,1+Q84/SUM(J84:P84),1) | H30: =IF(Supuestos!$E$30="Sí",R84,0) | I30: =E30-J30 | J30: =F30+G30+H30 | K30: =J30/E30
A31: =A85 | B31: =V85 | C31: =Supuestos!$B$30*S85 | D31: =MIN($J$6*U85,E85) | E31: =SUM(J85:Q85) | F31: =(MIN(C31,D85)*Y85+(MIN(H85,AA85)-MIN(H85,(V85-MIN(C31,D85))/($B$85*24*$L$6)))*AB85)*IF(Q85<0,1+Q85/SUM(J85:P85),1) | G31: =((MIN(H85,(V85-MIN(C31,D85))/($B$85*24*$L$6))-MIN(MAX(H85-MIN(Supuestos!$C$30,IF(T85>0,$J$6/T85,0)),0),(V85-MIN(C31,D85))/($B$85*24*$L$6)))*AB85+D31*Z85-D31/Supuestos!$B$18*X85)*IF(Q85<0,1+Q85/SUM(J85:P85),1) | H31: =IF(Supuestos!$E$30="Sí",R85,0) | I31: =E31-J31 | J31: =F31+G31+H31 | K31: =J31/E31
A32: =A86 | B32: =V86 | C32: =Supuestos!$B$30*S86 | D32: =MIN($J$6*U86,E86) | E32: =SUM(J86:Q86) | F32: =(MIN(C32,D86)*Y86+(MIN(H86,AA86)-MIN(H86,(V86-MIN(C32,D86))/($B$86*24*$L$6)))*AB86)*IF(Q86<0,1+Q86/SUM(J86:P86),1) | G32: =((MIN(H86,(V86-MIN(C32,D86))/($B$86*24*$L$6))-MIN(MAX(H86-MIN(Supuestos!$C$30,IF(T86>0,$J$6/T86,0)),0),(V86-MIN(C32,D86))/($B$86*24*$L$6)))*AB86+D32*Z86-D32/Supuestos!$B$18*X86)*IF(Q86<0,1+Q86/SUM(J86:P86),1) | H32: =IF(Supuestos!$E$30="Sí",R86,0) | I32: =E32-J32 | J32: =F32+G32+H32 | K32: =J32/E32
A33: =A87 | B33: =V87 | C33: =Supuestos!$B$30*S87 | D33: =MIN($J$6*U87,E87) | E33: =SUM(J87:Q87) | F33: =(MIN(C33,D87)*Y87+(MIN(H87,AA87)-MIN(H87,(V87-MIN(C33,D87))/($B$87*24*$L$6)))*AB87)*IF(Q87<0,1+Q87/SUM(J87:P87),1) | G33: =((MIN(H87,(V87-MIN(C33,D87))/($B$87*24*$L$6))-MIN(MAX(H87-MIN(Supuestos!$C$30,IF(T87>0,$J$6/T87,0)),0),(V87-MIN(C33,D87))/($B$87*24*$L$6)))*AB87+D33*Z87-D33/Supuestos!$B$18*X87)*IF(Q87<0,1+Q87/SUM(J87:P87),1) | H33: =IF(Supuestos!$E$30="Sí",R87,0) | I33: =E33-J33 | J33: =F33+G33+H33 | K33: =J33/E33
A34: =A88 | B34: =V88 | C34: =Supuestos!$B$30*S88 | D34: =MIN($J$6*U88,E88) | E34: =SUM(J88:Q88) | F34: =(MIN(C34,D88)*Y88+(MIN(H88,AA88)-MIN(H88,(V88-MIN(C34,D88))/($B$88*24*$L$6)))*AB88)*IF(Q88<0,1+Q88/SUM(J88:P88),1) | G34: =((MIN(H88,(V88-MIN(C34,D88))/($B$88*24*$L$6))-MIN(MAX(H88-MIN(Supuestos!$C$30,IF(T88>0,$J$6/T88,0)),0),(V88-MIN(C34,D88))/($B$88*24*$L$6)))*AB88+D34*Z88-D34/Supuestos!$B$18*X88)*IF(Q88<0,1+Q88/SUM(J88:P88),1) | H34: =IF(Supuestos!$E$30="Sí",R88,0) | I34: =E34-J34 | J34: =F34+G34+H34 | K34: =J34/E34
A35: =A89 | B35: =V89 | C35: =Supuestos!$B$30*S89 | D35: =MIN($J$6*U89,E89) | E35: =SUM(J89:Q89) | F35: =(MIN(C35,D89)*Y89+(MIN(H89,AA89)-MIN(H89,(V89-MIN(C35,D89))/($B$89*24*$L$6)))*AB89)*IF(Q89<0,1+Q89/SUM(J89:P89),1) | G35: =((MIN(H89,(V89-MIN(C35,D89))/($B$89*24*$L$6))-MIN(MAX(H89-MIN(Supuestos!$C$30,IF(T89>0,$J$6/T89,0)),0),(V89-MIN(C35,D89))/($B$89*24*$L$6)))*AB89+D35*Z89-D35/Supuestos!$B$18*X89)*IF(Q89<0,1+Q89/SUM(J89:P89),1) | H35: =IF(Supuestos!$E$30="Sí",R89,0) | I35: =E35-J35 | J35: =F35+G35+H35 | K35: =J35/E35
A36: =A90 | B36: =V90 | C36: =Supuestos!$B$30*S90 | D36: =MIN($J$6*U90,E90) | E36: =SUM(J90:Q90) | F36: =(MIN(C36,D90)*Y90+(MIN(H90,AA90)-MIN(H90,(V90-MIN(C36,D90))/($B$90*24*$L$6)))*AB90)*IF(Q90<0,1+Q90/SUM(J90:P90),1) | G36: =((MIN(H90,(V90-MIN(C36,D90))/($B$90*24*$L$6))-MIN(MAX(H90-MIN(Supuestos!$C$30,IF(T90>0,$J$6/T90,0)),0),(V90-MIN(C36,D90))/($B$90*24*$L$6)))*AB90+D36*Z90-D36/Supuestos!$B$18*X90)*IF(Q90<0,1+Q90/SUM(J90:P90),1) | H36: =IF(Supuestos!$E$30="Sí",R90,0) | I36: =E36-J36 | J36: =F36+G36+H36 | K36: =J36/E36
A37: =A91 | B37: =V91 | C37: =Supuestos!$B$30*S91 | D37: =MIN($J$6*U91,E91) | E37: =SUM(J91:Q91) | F37: =(MIN(C37,D91)*Y91+(MIN(H91,AA91)-MIN(H91,(V91-MIN(C37,D91))/($B$91*24*$L$6)))*AB91)*IF(Q91<0,1+Q91/SUM(J91:P91),1) | G37: =((MIN(H91,(V91-MIN(C37,D91))/($B$91*24*$L$6))-MIN(MAX(H91-MIN(Supuestos!$C$30,IF(T91>0,$J$6/T91,0)),0),(V91-MIN(C37,D91))/($B$91*24*$L$6)))*AB91+D37*Z91-D37/Supuestos!$B$18*X91)*IF(Q91<0,1+Q91/SUM(J91:P91),1) | H37: =IF(Supuestos!$E$30="Sí",R91,0) | I37: =E37-J37 | J37: =F37+G37+H37 | K37: =J37/E37
A38: TOTAL | B38: =SUM(B26:B37) | C38: =SUM(C26:C37) | D38: =SUM(D26:D37) | E38: =SUM(E26:E37) | F38: =SUM(F26:F37) | G38: =SUM(G26:G37) | H38: =SUM(H26:H37) | I38: =SUM(I26:I37) | J38: =SUM(J26:J37) | K38: =J38/E38
A39: Factor anualización (12/meses): | B39: 1
A40: 4. PROYECCIÓN 20 AÑOS — Comprar vs PPA/Ahorro compartido
A41: Año | B41: Tarifa Actual $ | C41: Ah PV $ | D41: Ah BESS $ | E41: Ah FP $ | F41: Costo c/proy $ | G41: Flujo Compra $ | H41: Pago PPA $ | I41: Comisión $ | J41: Flujo Cliente PPA $ | K41: Flujo Financiador $ | L41: Acum Compra $ | M41: Acum Cliente PPA $
A42: 0 | G42: =-B22 | K42: =-B22 | L42: =G42 | M42: 0
A43: 1 | B43: =$E$38*$B$39*(1+Supuestos!$B$8)^1 | C43: =$F$38*$B$39*(1+Supuestos!$B$8)^1*((1-Supuestos!$B$11)*(1-Supuestos!$B$12)^0) | D43: =$G$38*$B$39*(1+Supuestos!$B$8)^1*(1-Supuestos!$B$13)^1*Supuestos!$B$10 | E43: =$H$38*$B$39*(1+Supuestos!$B$8)^1 | F43: =B43-C43-D43-E43 | G43: =C43+D43+E43-(IF(1<=Supuestos!$J$30,Supuestos!$B$19*Supuestos!$B$30*(1+Supuestos!$B$8)^0,0)+IF(1<=Supuestos!$B$22,Supuestos!$B$20*Supuestos!$D$30*(1+Supuestos!$B$8)^0,0)) | H43: =IF(1<=Supuestos!$J$30,$C$38*$B$39*((1-Supuestos!$B$11)*(1-Supuestos!$B$12)^0)*Supuestos!$I$30*(1+Supuestos!$B$9)^0,0) | I43: =IF(1<=Supuestos!$B$22,D43*Supuestos!$K$30,0) | J43: =C43+D43+E43-H43-I43 | K43: =H43+I43-(IF(1<=Supuestos!$J$30,Supuestos!$B$19*Supuestos!$B$30*(1+Supuestos!$B$8)^0,0)+IF(1<=Supuestos!$B$22,Supuestos!$B$20*Supuestos!$D$30*(1+Supuestos!$B$8)^0,0))-H43*Supuestos!$B$21 | L43: =L42+G43 | M43: =M42+J43
