Workbook

Sheet Resumen
A1: GEPP — PROPUESTA SOLAR + BESS, 4 SITIOS | Resumen comparativo (MXN sin IVA) | jul-2026
A3: Sitio | B3: Opción / Esquema | C3: PV (kWp) | D3: BESS (kW) | E3: BESS (kWh) | F3: Gen (kWh/año) | G3: Gasto real hoy ($/año) | H3: Beneficio autoab. ($/año, →2032) | I3: Ahorro bruto ($) | J3: Pago PPA ($) | K3: Pago partic. ($) | L3: AHORRO NETO GEPP ($) | M3: % bruto | N3: % neto | O3: PPA (MXN/kWh) | P3: TIR PV | Q3: TIR BESS @50%
A4: Ixtlahuacán | B4: Op1: Autoconsumo | C4: ='Ixtlahuacán'!C26 -> 4550 | D4: ='Ixtlahuacán'!C28 -> 3700 | E4: ='Ixtlahuacán'!C29 -> 7400 | F4: ='Ixtlahuacán'!C41 -> 8114834 | G4: ='Ixtlahuacán'!N19 -> 52141327 | H4: ='Ixtlahuacán'!C38 -> 1649527 | I4: ='Ixtlahuacán'!C45 -> 25368712 | J4: ='Ixtlahuacán'!C46 -> 8343801.8 | K4: ='Ixtlahuacán'!C47 -> 5678437.2 | L4: ='Ixtlahuacán'!C48 -> 11346473 | M4: ='Ixtlahuacán'!C49 -> 0.48653752 | N4: ='Ixtlahuacán'!C50 -> 0.21760998 | O4: ='Ixtlahuacán'!C31 -> 1.0492 | P4: ='Ixtlahuacán'!C51 -> 0.14315285 | Q4: ='Ixtlahuacán'!C52 -> 0.1136277
B5: Op2: GD Medición Neta | C5: ='Ixtlahuacán'!D26 -> 839.45 | D5: ='Ixtlahuacán'!D28 -> 3700 | E5: ='Ixtlahuacán'!D29 -> 7400 | F5: ='Ixtlahuacán'!D41 -> 1497142.3 | G5: ='Ixtlahuacán'!N19 -> 52141327 | H5: ='Ixtlahuacán'!C38 -> 1649527 | I5: ='Ixtlahuacán'!D45 -> 13993338 | J5: ='Ixtlahuacán'!D46 -> 1539363.8 | K5: ='Ixtlahuacán'!D47 -> 5678437.2 | L5: ='Ixtlahuacán'!D48 -> 6775536.7 | M5: ='Ixtlahuacán'!D49 -> 0.26837325 | N5: ='Ixtlahuacán'!D50 -> 0.12994561 | O5: ='Ixtlahuacán'!D31 -> 1.0282 | P5: ='Ixtlahuacán'!D51 -> 0.14314976 | Q5: ='Ixtlahuacán'!D52 -> 0.1136277
A6: Acapulco | B6: Op1: Autoconsumo | C6: =Acapulco!C26 -> 1618 | D6: =Acapulco!C28 -> 1648 | E6: =Acapulco!C29 -> 3296 | F6: =Acapulco!C41 -> 3024766.9 | G6: =Acapulco!N19 -> 27061919 | H6: =Acapulco!C38 -> 0 | I6: =Acapulco!C45 -> 9819504 | J6: =Acapulco!C46 -> 2967232.1 | K6: =Acapulco!C47 -> 2090144.8 | L6: =Acapulco!C48 -> 4762127.1 | M6: =Acapulco!C49 -> 0.3628532 | N6: =Acapulco!C50 -> 0.17597152 | O6: =Acapulco!C31 -> 1.001 | P6: =Acapulco!C51 -> 0.1431631 | Q6: =Acapulco!C52 -> 0.071985139
B7: Op2: GD Medición Neta | C7: =Acapulco!D26 -> 839.45 | D7: =Acapulco!D28 -> 1648 | E7: =Acapulco!D29 -> 3296 | F7: =Acapulco!D41 -> 1569308.1 | G7: =Acapulco!N19 -> 27061919 | H7: =Acapulco!C38 -> 0 | I7: =Acapulco!D45 -> 7285068.6 | J7: =Acapulco!D46 -> 1539495.2 | K7: =Acapulco!D47 -> 2090144.8 | L7: =Acapulco!D48 -> 3655428.6 | M7: =Acapulco!D49 -> 0.2692 | N7: =Acapulco!D50 -> 0.13507647 | O7: =Acapulco!D31 -> 0.981 | P7: =Acapulco!D51 -> 0.14316836 | Q7: =Acapulco!D52 -> 0.071985139
A8: Cancún | B8: Op1: Autoconsumo | C8: ='Cancún'!C26 -> 1100 | D8: ='Cancún'!C28 -> 981 | E8: ='Cancún'!C29 -> 1962 | F8: ='Cancún'!C41 -> 1649771.2 | G8: ='Cancún'!N19 -> 15152838 | H8: ='Cancún'!C38 -> 0 | I8: ='Cancún'!C45 -> 6277408.3 | J8: ='Cancún'!C46 -> 2017227.2 | K8: ='Cancún'!C47 -> 1372048.8 | L8: ='Cancún'!C48 -> 2888132.3 | M8: ='Cancún'!C49 -> 0.41427278 | N8: ='Cancún'!C50 -> 0.19060009 | O8: ='Cancún'!C31 -> 1.2476 | P8: ='Cancún'!C51 -> 0.14315765 | Q8: ='Cancún'!C52 -> 0.093055732
B9: Op2: GD Medición Neta | C9: ='Cancún'!D26 -> 839.45 | D9: ='Cancún'!D28 -> 981 | E9: ='Cancún'!D29 -> 1962 | F9: ='Cancún'!D41 -> 1259000.4 | G9: ='Cancún'!N19 -> 15152838 | H9: ='Cancún'!C38 -> 0 | I9: ='Cancún'!D45 -> 5511211 | J9: ='Cancún'!D46 -> 1539383.4 | K9: ='Cancún'!D47 -> 1372048.8 | L9: ='Cancún'!D48 -> 2599778.7 | M9: ='Cancún'!D49 -> 0.36370817 | N9: ='Cancún'!D50 -> 0.17157042 | O9: ='Cancún'!D31 -> 1.2227 | P9: ='Cancún'!D51 -> 0.14315255 | Q9: ='Cancún'!D52 -> 0.093055732
A10: Proplasa | B10: Op1: 2×GD + Autoconsumo | C10: =Proplasa!C26 -> 3848.9 | D10: =Proplasa!C28 -> 11787 | E10: =Proplasa!C29 -> 23574 | F10: =Proplasa!C41 -> 6389820.6 | G10: =Proplasa!N19 -> 202250117 | H10: =Proplasa!C38 -> 57664106 | I10: =Proplasa!C45 -> 50181166 | J10: =Proplasa!C46 -> 7058195.9 | K10: =Proplasa!C47 -> 19088041 | L10: =Proplasa!C48 -> 24034930 | M10: =Proplasa!C49 -> 0.2481144 | N10: =Proplasa!C50 -> 0.11883766 | O10: =Proplasa!C31 -> 1.1046 | P10: =Proplasa!C51 -> 0.14315511 | Q10: =Proplasa!C52 -> 0.12584659
B11: Op2: 3× GD Medición Neta | C11: =Proplasa!D26 -> 2518.35 | D11: =Proplasa!D28 -> 11787 | E11: =Proplasa!D29 -> 23574 | F11: =Proplasa!D41 -> 4180884.1 | G11: =Proplasa!N19 -> 202250117 | H11: =Proplasa!C38 -> 57664106 | I11: =Proplasa!D45 -> 46033331 | J11: =Proplasa!D46 -> 4618204.6 | K11: =Proplasa!D47 -> 19088041 | L11: =Proplasa!D48 -> 22327086 | M11: =Proplasa!D49 -> 0.22760595 | N11: =Proplasa!D50 -> 0.11039344 | O11: =Proplasa!D31 -> 1.1046 | P11: =Proplasa!D51 -> 0.14315511 | Q11: =Proplasa!D52 -> 0.12584659
A13: PORTAFOLIO | B13: Suma Opción 1 | C13: =C4+C6+C8+C10 -> 11116.9 | D13: =D4+D6+D8+D10 -> 18116 | E13: =E4+E6+E8+E10 -> 36232 | F13: =F4+F6+F8+F10 -> 19179193 | G13: =G4+G6+G8+G10 -> 296606201 | H13: =H4+H6+H8+H10 -> 59313633 | I13: =I4+I6+I8+I10 -> 91646790 | J13: =J4+J6+J8+J10 -> 20386457 | ... L13: =L4+L6+L8+L10 -> 43031662
B14: Suma Opción 2 | C14: =C5+C7+C9+C11 -> 5036.7 | D14: =D5+D7+D9+D11 -> 18116 | E14: =E5+E7+E9+E11 -> 36232 | F14: =F5+F7+F9+F11 -> 8506334.9 | G14: =G5+G7+G9+G11 -> 296606201 | H14: =H5+H7+H9+H11 -> 59313633 | I14: =I5+I7+I9+I11 -> 72822948 | J14: =J5+J7+J9+J11 -> 9236447 | ... L14: =L5+L7+L9+L11 -> 35357830
A16: Nota: "Gasto real hoy" ya refleja el descuento de autoabasto; el "Beneficio autoab." (naranja) se pierde en 2032 → el gasto real del cliente salta en 2033 (ver proyección 20 años de cada sitio). Nuestro ahorro $ es el hedge.

Sheet Supuestos
A1: SUPUESTOS DEL MODELO — editar celdas amarillas (todo sin IVA)
A4: Tipo de cambio (MXN/USD) | B4: 17.55 | C4: MXN/USD
A5: Precio de venta PV (USD/Wp) | B5: 0.65 | C5: USD/Wp
A6: Costo duro PV — informativo (USD/Wp) | B6: 0.5 | C6: USD/Wp
A7: Precio BESS instalado (USD/Wh) | B7: 0.28 | C7: USD/Wh
A8: Costo FOB BESS — informativo (USD/Wh) | B8: 0.18 | C8: USD/Wh
A9: Escalación tarifas CFE (anual) | B9: 0.04 | C9: %
A10: Escalación precio PPA (anual) | B10: 0.04 | C10: %
A11: Degradación PV (anual) | B11: 0.005 | C11: %
A12: Degradación BESS (anual) | B12: 0.0125 | C12: %
A13: Profundidad de descarga BESS (DoD) | B13: 0.96
A14: Eficiencia round-trip BESS (RTE) | B14: 0.96
A15: Factor de carga p/ umbral de demanda | B15: 0.57
A16: Meses sin ahorro BESS al año (merma de riesgo) | B16: 2 | C16: meses
A17: Participación del inversionista en ahorro BESS | B17: 0.5 | C17: %
A18: Plazo PPA / venta de energía PV (años) | B18: 15 | C18: años
A19: Plazo BESS / participación en ahorro (años) | B19: 15 | C19: años
A20: Horizonte de análisis (años) | B20: 20 | C20: años
A21: Tasa de descuento / WACC | B21: 0.12 | C21: %
A22: O&M PV (MXN/kWp·año) | B22: 310 | C22: MXN/kWp
A23: O&M BESS (MXN/kWh·año) | B23: 180 | C23: MXN/kWh
A24: Densidad de instalación (m²/kWp) | B24: 4 | C24: m²/kWp
A25: Año base del modelo (Año 1) | B25: 2026 | C25: año
A26: Año de término autoabasto TALA / ENEL | B26: 2032 | C26: año
A29: SITIOS — recurso solar y superficie
A30: Sitio | B30: Municipio | C30: Tarifa | D30: Yield (kWh/kWp·año) | E30: Superficie disp. (m²)
A31: Sitio | B31: Municipio | C31: Tarifa | D31: Yield (kWh/kWp·año) | E31: Superficie disp. (m²)
A32: Ixtlahuacán | B32: Ixtlahuacán de los Membrillos, Jal. | C32: DIST (Jalisco) | D32: 1783 | E32: 25308
A33: Acapulco | B33: Acapulco de Juárez, Gro. | C33: GDMTH (Centro Sur) | D33: 1869 | E33: 7019
A34: Cancún | B34: Benito Juárez, Q.R. | C34: GDMTH (Peninsular) | D34: 1500 | E34: 6828
A35: Proplasa | B35: Cuautitlán Izcalli, Méx. | C35: GDMTH (V. de México Norte) | D35: 1660 | E35: 15396
A38: SUPUESTOS Y NOTAS CLAVE
A39: • Baseline: últimos 12 meses reales may-25 → abr-26 (recibos CFE, sin IVA).
A40: • Autoabasto TALA (Ixtlahuacán, zafra) y ENEL (Proplasa) vencen 2032. Su beneficio actual se
A41: cuantifica por sitio (fila "Beneficio autoabasto") y aparece en la proyección 20 años como la
A42: brecha entre "Gasto CFE pleno" y "Gasto real"; esa brecha se cierra en 2033 → el gasto real del
A43: cliente DA UN SALTO. El ahorro $ de nuestro sistema (PPA fijo) no cambia, por lo que cubre un %
A44: menor de un recibo mayor, pero es justo el hedge que amortigua ese salto. Editar beneficio y año.
A45: • Plazo PPA y plazo BESS ahora son independientes (celdas B18/B19). Ej.: 12 años PPA + 20 de
A46: participación en ahorro BESS. Tras el plazo PPA el ahorro PV queda 100% para GEPP (pago=0).
...

Sheet Ixtlahuacán
A1: GEPP Ixtlahuacán — Propuesta Solar + BESS | DIST (Jalisco) | Ixtlahuacán de los Membrillos, Jal. (montos MXN sin IVA)
A3: 1. DATOS BASE — últimos 12 meses reales (recibos CFE, sin IVA)
A4: Mes | B4: may-25 | C4: jun-25 | D4: jul-25 | E4: ago-25 | F4: sep-25 | G4: oct-25 | H4: nov-25 | I4: dic-25 | J4: ene-26 | K4: feb-26 | L4: mar-26 | M4: abr-26 | N4: TOTAL
A5: Consumo Base (kWh) | B5: 664426 | C5: 630738 | D5: 534017 | E5: 701321 | F5: 593175 | G5: 641906 | H5: 719936 | I5: 704647 | J5: 591649 | K5: 449327 | L5: 725263 | M5: 574838 | N5: =SUM(B5:M5) -> 7531243
A6: Consumo Intermedia (kWh) | B6: 1271980 | C6: 1133752 | D6: 1146833 | E6: 1065260 | F6: 941250 | G6: 1065460 | H6: 965437 | I6: 1049782 | J6: 969708 | K6: 811294 | L6: 1035362 | M6: 1202190 | N6: =SUM(B6:M6) -> 12658308
A7: Consumo Punta (kWh) | B7: 118279 | C7: 116822 | D7: 122085 | E7: 176568 | F7: 167798 | G7: 218540 | H7: 254095 | I7: 282952 | J7: 268637 | K7: 148414 | L7: 178884 | M7: 135622 | N7: =SUM(B7:M7) -> 2188696
A8: Consumo Total (kWh) | B8: =SUM(B5:B7) -> 2054685 | C8: =SUM(C5:C7) -> 1881312 | D8: =SUM(D5:D7) -> 1802935 | E8: =SUM(E5:E7) -> 1943149 | F8: =SUM(F5:F7) -> 1702223 | G8: =SUM(G5:G7) -> 1925906 | H8: =SUM(H5:H7) -> 1939468 | I8: =SUM(I5:I7) -> 2037381 | ... M8: =SUM(M5:M7) -> 1912650 | N8: =SUM(B8:M8) -> 22378247
A9: Dem. máx. en punta (kW) | B9: 2688 | C9: 2781 | D9: 2654 | E9: 4204 | F9: 3814 | G9: 4361 | H9: 3102 | I9: 3105 | J9: 3011 | K9: 1852 | L9: 2045 | M9: 2926 | N9: =MAX(B9:M9) -> 4361
A10: Dem. máx. mensual (kW) | B10: 3011 | C10: 2799 | D10: 2655 | E10: 4204 | F10: 3814 | G10: 4361 | H10: 3714 | I10: 3760 | J10: 3128 | K10: 2589 | L10: 3687 | M10: 3138 | N10: =MAX(B10:M10) -> 4361
A11: Días con punta | B11: 22 | C11: 21 | D11: 23 | E11: 21 | F11: 22 | G11: 23 | H11: 25 | I11: 27 | J11: 27 | K11: 24 | L11: 26 | M11: 23
A12: Horas punta/día | B12: 2 | C12: 2 | D12: 2 | E12: 2 | F12: 2 | G12: 2.43 | H12: 3.6 | I12: 3.7 | J12: 3.63 | K12: 3.67 | L12: 3.69 | M12: 2.26
A13: Días del mes | B13: 31 | C13: 30 | D13: 31 | E13: 31 | F13: 30 | G13: 31 | H13: 30 | I13: 31 | J13: 31 | K13: 28 | L13: 31 | M13: 30
A14: Tarifa Base ($/kWh) | B14: 1.1444 | C14: 1.1669 | D14: 1.1815 | E14: 1.1829 | F14: 1.178 | G14: 1.178 | H14: 1.1485 | I14: 1.101 | J14: 1.0776 | K14: 1.0781 | L14: 1.0786 | M14: 1.0786
A15: Tarifa Intermedia ($/kWh) | B15: 1.8911 | C15: 1.9314 | D15: 1.9575 | E15: 1.96 | F15: 1.9479 | G15: 1.9479 | H15: 1.8954 | I15: 1.8105 | J15: 1.7711 | K15: 1.772 | L15: 1.773 | M15: 1.7729
A16: Tarifa Punta ($/kWh) | B16: 2.2374 | C16: 2.2859 | D16: 2.3173 | E16: 2.3203 | F16: 2.3049 | G16: 2.3049 | H16: 2.2417 | I16: 2.1395 | J16: 2.0927 | K16: 2.0938 | L16: 2.0949 | M16: 2.0948
A17: Tarifa Capacidad ($/kW·mes) | B17: 432.62 | C17: 442.9 | D17: 449.54 | E17: 450.17 | F17: 446.05 | G17: 446.06 | H17: 432.66 | I17: 411.03 | J17: 401.78 | K17: 402 | L17: 402.26 | M17: 402.24
A18: Tarifa Distribución ($/kW·mes) | B18: 0 | C18: 0 | D18: 0 | E18: 0 | F18: 0 | G18: 0 | H18: 0 | I18: 0 | J18: 0 | K18: 0 | L18: 0 | M18: 0 | O18: FC umbral (DIST)
A19: Gasto actual facturado ($ MXN) | B19: 4462726 | C19: 4700643 | D19: 4627503 | E19: 4932162 | F19: 4336535 | G19: 4904162 | H19: 4836407 | I19: 4353098 | J19: 3828426 | K19: 3026757 | L19: 3987520 | M19: 4145388 | N19: =SUM(B19:M19) -> 52141327 | O19: GDMTH=0.57 · DIST=0.74
A20: Umbral de demanda (kW) — FC DIST 0.74 | B20: =B8/(24*B13*$O$20) -> 3731.9911 | C20: =C8/(24*C13*$O$20) -> 3530.991 | D20: =D8/(24*D13*$O$20) -> 3274.7294 | E20: =E8/(24*E13*$O$20) -> 3529.4046 | F20: =F8/(24*F13*$O$20) -> 3194.863 | G20: =G8/(24*G13*$O$20) -> 3498.0856 | H20: =H8/(24*H13*$O$20) -> 3640.1426 | I20: =I8/(24*I13*$O$20) -> 3700.5612 | ... M20: =M8/(24*M13*$O$20) -> 3589.8086 | O20: 0.74
A21: Yield PV (kWh/kWp) | B21: 162.688 | C21: 148.08 | D21: 138.632 | E21: 131.688 | F21: 126.72 | G21: 146.816 | H21: 151.92 | I21: 138.384 | J21: 147.064 | K21: 142.464 | L21: 180.544 | M21: 168.48 | N21: =SUM(B21:M21) -> 1783.48
A23: 2. SISTEMA PROPUESTO — Opción 1 y Opción 2 (amarillo = editable)
A24: Concepto | C24: OPCIÓN 1 — Autoconsumo | D24: OPCIÓN 2 — GD Medición Neta
A25: Esquema legal | C25: Autoconsumo interconectado (permiso CNE simplificado) | D25: Generación Distribuida <0.7 MW (sin permiso)
A26: Potencia PV (kWp DC) | C26: 4550 | D26: 839.45
A27: Superficie requerida (m²) | C27: =C26*Supuestos!$B$24 -> 18200 | D27: =D26*Supuestos!$B$24 -> 3357.8
A28: BESS potencia (kW) | C28: 3700 | D28: 3700
A29: BESS capacidad (kWh) | C29: 7400 | D29: 7400
A30: Energía útil BESS (kWh) | C30: =C29*Supuestos!$B$13*SQRT(Supuestos!$B$14) -> 6960.4701 | D30: =D29*Supuestos!$B$13*SQRT(Supuestos!$B$14) -> 6960.4701
A31: Precio PPA (MXN/kWh, año 1) | C31: 1.2848231 | D31: 1.5031642
A32: Participación inversionista BESS (%) | C32: =Supuestos!$B$17 -> 0.5 | D32: =Supuestos!$B$17 -> 0.5
A33: CAPEX PV (USD) | C33: =C26*1000*Supuestos!$B$5 -> 2957500 | D33: =D26*1000*Supuestos!$B$5 -> 545642.5
A34: CAPEX PV (MXN) | C34: =C33*Supuestos!$B$4 -> 51904125 | D34: =D33*Supuestos!$B$4 -> 9576025.9
A35: CAPEX BESS (USD) | C35: =C29*1000*Supuestos!$B$7 -> 2072000 | D35: =D29*1000*Supuestos!$B$7 -> 2072000
A36: CAPEX BESS (MXN) | C36: =C35*Supuestos!$B$4 -> 36363600 | D36: =D35*Supuestos!$B$4 -> 36363600
A37: — Autoabasto TALA / ENEL (vence 2032) —
A38: Beneficio autoabasto actual ($/año) | C38: 1649527 | D38: =C38 -> 1649527
A39: Gasto sin autoabasto — CFE pleno ($/año) | C39: =$N$19+C38 -> 53790854 | D39: =$N$19+D38 -> 53790854
A40: Gasto real hoy (con autoabasto) ($/año) | C40: =C39-C38 -> 52141327 | D40: =D39-D38 -> 52141327
A41: Generación PV año 1 (kWh) | C41: =C72 -> 8114834 | D41: =C89 -> 1497142.3
A42: Energía facturada al PPA (kWh) | C42: =K72 -> 7952537 | D42: =K89 -> 1497144.3
...

Sheet Acapulco
A1: GEPP Acapulco — Propuesta Solar + BESS | GDMTH (Centro Sur) | Acapulco de Juárez, Gro. (montos MXN sin IVA)
A3: 1. DATOS BASE — últimos 12 meses reales (recibos CFE, sin IVA)
A4: Mes | B4: may-25 | C4: jun-25 | D4: jul-25 | E4: ago-25 | F4: sep-25 | G4: oct-25 | H4: nov-25 | I4: dic-25 | J4: ene-26 | K4: feb-26 | L4: mar-26 | M4: abr-26 | N4: TOTAL
A5: Consumo Base (kWh) | B5: 312618 | C5: 233673 | D5: 213143 | E5: 210539 | F5: 197847 | G5: 172712 | H5: 248446 | I5: 268553 | J5: 172176 | K5: 167957 | L5: 206958 | M5: 210087 | N5: =SUM(B5:M5) -> 2614709
A6: Consumo Intermedia (kWh) | B6: 506177 | C6: 395913 | D6: 485674 | E6: 466847 | F6: 411635 | G6: 415203 | H6: 348173 | I6: 419527 | J6: 362748 | K6: 300801 | L6: 391377 | M6: 464168 | N6: =SUM(B6:M6) -> 4968243
A7: Consumo Punta (kWh) | B7: 49413 | C7: 42282 | D7: 56718 | E7: 44577 | F7: 49268 | G7: 56344 | H7: 86947 | I7: 116821 | J7: 101854 | K7: 87531 | L7: 105161 | M7: 60762 | N7: =SUM(B7:M7) -> 857678
A8: Consumo Total (kWh) | B8: =SUM(B5:B7) -> 868208 | C8: =SUM(C5:C7) -> 671868 | D8: =SUM(D5:D7) -> 755535 | E8: =SUM(E5:E7) -> 721963 | F8: =SUM(F5:F7) -> 658750 | G8: =SUM(G5:G7) -> 644259 | H8: =SUM(H5:H7) -> 683566 | I8: =SUM(I5:I7) -> 804901 | ... M8: =SUM(M5:M7) -> 735017 | N8: =SUM(B8:M8) -> 8440630
A9: Dem. máx. en punta (kW) | B9: 1123 | C9: 1007 | D9: 1233 | E9: 1061 | F9: 1120 | G9: 1124 | H9: 1061 | I9: 1282 | J9: 1141 | K9: 1092 | L9: 1202 | M9: 1311 | N9: =MAX(B9:M9) -> 1311
A10: Dem. máx. mensual (kW) | B10: 1417 | C10: 1033 | D10: 1233 | E10: 1108 | F10: 1120 | G10: 1124 | H10: 1282 | I10: 1433 | J10: 1141 | K10: 1092 | L10: 1202 | M10: 1311 | N10: =MAX(B10:M10) -> 1433
A11: Días con punta | B11: 22 | C11: 21 | D11: 23 | E11: 21 | F11: 22 | G11: 23 | H11: 25 | I11: 27 | J11: 27 | K11: 24 | L11: 26 | M11: 23
A12: Horas punta/día | B12: 2 | C12: 2 | D12: 2 | E12: 2 | F12: 2 | G12: 2.43 | H12: 3.6 | I12: 3.7 | J12: 3.63 | K12: 3.67 | L12: 3.69 | M12: 2.26
A13: Días del mes | B13: 31 | C13: 30 | D13: 31 | E13: 31 | F13: 30 | G13: 31 | H13: 30 | I13: 31 | J13: 31 | K13: 28 | L13: 31 | M13: 30
A14: Tarifa Base ($/kWh) | B14: 1.0246 | C14: 1.0444 | D14: 1.0571 | E14: 1.0583 | F14: 1.0545 | G14: 1.0545 | H14: 1.0288 | I14: 0.9872 | J14: 0.9664 | K14: 0.9668 | L14: 0.9673 | M14: 0.9673
A15: Tarifa Intermedia ($/kWh) | B15: 1.8215 | C15: 1.8602 | D15: 1.8852 | E15: 1.8875 | F15: 1.8761 | G15: 1.8761 | H15: 1.8257 | I15: 1.7443 | J15: 1.7064 | K15: 1.7073 | L15: 1.7082 | M15: 1.7082
A16: Tarifa Punta ($/kWh) | B16: 2.0638 | C16: 2.1082 | D16: 2.1369 | E16: 2.1396 | F16: 2.1259 | G16: 2.1259 | H16: 2.068 | I16: 1.9745 | J16: 1.9314 | K16: 1.9325 | L16: 1.9335 | M16: 1.9334
A17: Tarifa Capacidad ($/kW·mes) | B17: 392.89 | C17: 402.23 | D17: 408.26 | E17: 408.83 | F17: 405.09 | G17: 405.09 | H17: 392.93 | I17: 373.28 | J17: 364.88 | K17: 365.09 | L17: 365.31 | M17: 365.3
A18: Tarifa Distribución ($/kW·mes) | B18: 230.35 | C18: 230.35 | D18: 230.35 | E18: 230.35 | F18: 230.35 | G18: 230.35 | H18: 230.35 | I18: 230.35 | J18: 221.09 | K18: 221.09 | L18: 221.09 | M18: 221.09
A19: Gasto actual facturado ($ MXN) | B19: 2520372 | C19: 2223521 | D19: 2510130 | E19: 2435442 | F19: 2253138 | G19: 2183503 | H19: 2247709 | I19: 2457378 | J19: 1987516 | K19: 1813798 | L19: 2181066 | M19: 2248346 | N19: =SUM(B19:M19) -> 27061919
A20: Umbral de demanda (kW) | B20: =B8/(24*B13*Supuestos!$B$15) -> 2047.2741 | C20: =C8/(24*C13*Supuestos!$B$15) -> 1637.1053 | D20: =D8/(24*D13*Supuestos!$B$15) -> 1781.586 | E20: =E8/(24*E13*Supuestos!$B$15) -> 1702.4217 | F20: =F8/(24*F13*Supuestos!$B$15) -> 1605.1413 | G20: =G8/(24*G13*Supuestos!$B$15) -> 1519.1921 | H20: =H8/(24*H13*Supuestos!$B$15) -> 1665.6092 | I20: =I8/(24*I13*Supuestos!$B$15) -> 1897.9933 | ... M20: =M8/(24*M13*Supuestos!$B$15) -> 1790.9771
A21: Yield PV (kWh/kWp) | B21: 166.408 | C21: 146.88 | D21: 156.984 | E21: 143.592 | F21: 129.84 | G21: 152.768 | H21: 154.32 | I21: 153.264 | J21: 159.712 | K21: 150.528 | L21: 184.512 | M21: 170.64 | N21: =SUM(B21:M21) -> 1869.448
A23: 2. SISTEMA PROPUESTO — Opción 1 y Opción 2 (amarillo = editable)
A24: Concepto | C24: OPCIÓN 1 — Autoconsumo | D24: OPCIÓN 2 — GD Medición Neta
A25: Esquema legal | C25: Autoconsumo interconectado (permiso CNE simplificado) | D25: Generación Distribuida <0.7 MW (sin permiso)
A26: Potencia PV (kWp DC) | C26: 1618 | D26: 839.45
A27: Superficie requerida (m²) | C27: =C26*Supuestos!$B$24 -> 6472 | D27: =D26*Supuestos!$B$24 -> 3357.8
A28: BESS potencia (kW) | C28: 1648 | D28: 1648
A29: BESS capacidad (kWh) | C29: 3296 | D29: 3296
A30: Energía útil BESS (kWh) | C30: =C29*Supuestos!$B$13*SQRT(Supuestos!$B$14) -> 3100.231 | D30: =D29*Supuestos!$B$13*SQRT(Supuestos!$B$14) -> 3100.231
A31: Precio PPA (MXN/kWh, año 1) | C31: 1.2257987 | D31: 1.4341607
A32: Participación inversionista BESS (%) | C32: =Supuestos!$B$17 -> 0.5 | D32: =Supuestos!$B$17 -> 0.5
A33: CAPEX PV (USD) | C33: =C26*1000*Supuestos!$B$5 -> 1051700 | D33: =D26*1000*Supuestos!$B$5 -> 545642.5
A34: CAPEX PV (MXN) | C34: =C33*Supuestos!$B$4 -> 18457335 | D34: =D33*Supuestos!$B$4 -> 9576025.9
A35: CAPEX BESS (USD) | C35: =C29*1000*Supuestos!$B$7 -> 922880 | D35: =D29*1000*Supuestos!$B$7 -> 922880
A36: CAPEX BESS (MXN) | C36: =C35*Supuestos!$B$4 -> 16196544 | D36: =D35*Supuestos!$B$4 -> 16196544
A37: — Autoabasto TALA / ENEL (vence 2032) —
A38: Beneficio autoabasto actual ($/año) | C38: 0 | D38: =C38 -> 0
A39: Gasto sin autoabasto — CFE pleno ($/año) | C39: =$N$19+C38 -> 27061919 | D39: =$N$19+D38 -> 27061919
A40: Gasto real hoy (con autoabasto) ($/año) | C40: =C39-C38 -> 27061919 | D40: =D39-D38 -> 27061919
A41: Generación PV año 1 (kWh) | C41: =C72 -> 3024766.9 | D41: =C89 -> 1569308.1
A42: Energía facturada al PPA (kWh) | C42: =K72 -> 2964267.8 | D42: =K89 -> 1569312.1
...

Sheet Cancún
A1: GEPP Cancún — Propuesta Solar + BESS | GDMTH (Peninsular) | Benito Juárez, Q.R. (montos MXN sin IVA)
A3: 1. DATOS BASE — últimos 12 meses reales (recibos CFE, sin IVA)
A4: Mes | B4: may-25 | C4: jun-25 | D4: jul-25 | E4: ago-25 | F4: sep-25 | G4: oct-25 | H4: nov-25 | I4: dic-25 | J4: ene-26 | K4: feb-26 | L4: mar-26 | M4: abr-26 | N4: TOTAL
A5: Consumo Base (kWh) | B5: 131219 | C5: 135885 | D5: 101439 | E5: 116365 | F5: 100169 | G5: 98572 | H5: 94126 | I5: 102510 | J5: 100399 | K5: 112612 | L5: 121096 | M5: 87120 | N5: =SUM(B5:M5) -> 1301512
A6: Consumo Intermedia (kWh) | B6: 271299 | C6: 268040 | D6: 274792 | E6: 275738 | F6: 231786 | G6: 224586 | H6: 183552 | I6: 225061 | J6: 190456 | K6: 186342 | L6: 201871 | M6: 213852 | N6: =SUM(B6:M6) -> 2747375
A7: Consumo Punta (kWh) | B7: 30661 | C7: 30139 | D7: 34785 | E7: 28280 | F7: 26471 | G7: 35922 | H7: 53993 | I7: 64699 | J7: 54255 | K7: 51438 | L7: 55161 | M7: 28376 | N7: =SUM(B7:M7) -> 494180
A8: Consumo Total (kWh) | B8: =SUM(B5:B7) -> 433179 | C8: =SUM(C5:C7) -> 434064 | D8: =SUM(D5:D7) -> 411016 | E8: =SUM(E5:E7) -> 420383 | F8: =SUM(F5:F7) -> 358426 | G8: =SUM(G5:G7) -> 359080 | H8: =SUM(H5:H7) -> 331671 | I8: =SUM(I5:I7) -> 392270 | ... M8: =SUM(M5:M7) -> 329348 | N8: =SUM(B8:M8) -> 4543067
A9: Dem. máx. en punta (kW) | B9: 697 | C9: 718 | D9: 756 | E9: 673 | F9: 602 | G9: 717 | H9: 659 | I9: 710 | J9: 608 | K9: 642 | L9: 631 | M9: 612 | N9: =MAX(B9:M9) -> 756
A10: Dem. máx. mensual (kW) | B10: 697 | C10: 718 | D10: 756 | E10: 673 | F10: 602 | G10: 717 | H10: 659 | I10: 710 | J10: 608 | K10: 649 | L10: 631 | M10: 612 | N10: =MAX(B10:M10) -> 756
A11: Días con punta | B11: 22 | C11: 21 | D11: 23 | E11: 21 | F11: 22 | G11: 23 | H11: 25 | I11: 27 | J11: 27 | K11: 24 | L11: 26 | M11: 23
A12: Horas punta/día | B12: 2 | C12: 2 | D12: 2 | E12: 2 | F12: 2 | G12: 2.43 | H12: 3.6 | I12: 3.7 | J12: 3.63 | K12: 3.67 | L12: 3.69 | M12: 2.26
A13: Días del mes | B13: 31 | C13: 30 | D13: 31 | E13: 31 | F13: 30 | G13: 31 | H13: 30 | I13: 31 | J13: 31 | K13: 28 | L13: 31 | M13: 30
A14: Tarifa Base ($/kWh) | B14: 1.3138 | C14: 1.3404 | D14: 1.3576 | E14: 1.3593 | F14: 1.3527 | G14: 1.3527 | H14: 1.318 | I14: 1.262 | J14: 1.235 | K14: 1.2356 | L14: 1.2362 | M14: 1.2362
A15: Tarifa Intermedia ($/kWh) | B15: 2.2227 | C15: 2.2709 | D15: 2.3021 | E15: 2.305 | F15: 2.2898 | G15: 2.2898 | H15: 2.227 | I15: 2.1256 | J15: 2.0791 | K15: 2.0802 | L15: 2.0813 | M15: 2.0812
A16: Tarifa Punta ($/kWh) | B16: 2.4821 | C16: 2.5365 | D16: 2.5716 | E16: 2.5749 | F16: 2.5572 | G16: 2.5572 | H16: 2.4864 | I16: 2.372 | J16: 2.32 | K16: 2.3212 | L16: 2.3225 | M16: 2.3224
A17: Tarifa Capacidad ($/kW·mes) | B17: 422.31 | C17: 432.34 | D17: 438.82 | E17: 439.43 | F17: 435.41 | G17: 435.41 | H17: 422.34 | I17: 401.23 | J17: 392.2 | K17: 392.43 | L17: 392.66 | M17: 392.65
A18: Tarifa Distribución ($/kW·mes) | B18: 94.61 | C18: 94.61 | D18: 94.61 | E18: 94.61 | F18: 94.61 | G18: 94.61 | H18: 94.61 | I18: 94.61 | J18: 91.87 | K18: 91.87 | L18: 91.87 | M18: 91.87
A19: Gasto actual facturado ($ MXN) | B19: 1428537 | C19: 1476755 | D19: 1432719 | E19: 1449835 | F19: 1246694 | G19: 1242022 | H19: 1133482 | I19: 1270329 | J19: 1087142 | K19: 1138796 | L19: 1181496 | M19: 1065031 | N19: =SUM(B19:M19) -> 15152838
A20: Umbral de demanda (kW) | B20: =B8/(24*B13*Supuestos!$B$15) -> 1021.4559 | C20: =C8/(24*C13*Supuestos!$B$15) -> 1057.6608 | D20: =D8/(24*D13*Supuestos!$B$15) -> 969.19449 | E20: =E8/(24*E13*Supuestos!$B$15) -> 991.28231 | F20: =F8/(24*F13*Supuestos!$B$15) -> 873.3577 | G20: =G8/(24*G13*Supuestos!$B$15) -> 846.72703 | H20: =H8/(24*H13*Supuestos!$B$15) -> 808.1652 | I20: =I8/(24*I13*Supuestos!$B$15) -> 924.99057 | ... M20: =M8/(24*M13*Supuestos!$B$15) -> 802.50487
A21: Yield PV (kWh/kWp) | B21: 139.624 | C21: 127.44 | D21: 131.192 | E21: 123.256 | F21: 118.32 | G21: 121.768 | H21: 114.96 | I21: 112.592 | J21: 116.312 | K21: 113.792 | L21: 140.616 | M21: 139.92 | N21: =SUM(B21:M21) -> 1499.792
A23: 2. SISTEMA PROPUESTO — Opción 1 y Opción 2 (amarillo = editable)
A24: Concepto | C24: OPCIÓN 1 — Autoconsumo | D24: OPCIÓN 2 — GD Medición Neta
A25: Esquema legal | C25: Autoconsumo interconectado (permiso CNE simplificado) | D25: Generación Distribuida <0.7 MW (sin permiso)
A26: Potencia PV (kWp DC) | C26: 1100 | D26: 839.45
A27: Superficie requerida (m²) | C27: =C26*Supuestos!$B$24 -> 4400 | D27: =D26*Supuestos!$B$24 -> 3357.8
A28: BESS potencia (kW) | C28: 981 | D28: 981
A29: BESS capacidad (kWh) | C29: 1962 | D29: 1962
A30: Energía útil BESS (kWh) | C30: =C29*Supuestos!$B$13*SQRT(Supuestos!$B$14) -> 1845.4652 | D30: =D29*Supuestos!$B$13*SQRT(Supuestos!$B$14) -> 1845.4652
A31: Precio PPA (MXN/kWh, año 1) | C31: 1.5277786 | D31: 1.787511
A32: Participación inversionista BESS (%) | C32: =Supuestos!$B$17 -> 0.5 | D32: =Supuestos!$B$17 -> 0.5
A33: CAPEX PV (USD) | C33: =C26*1000*Supuestos!$B$5 -> 715000 | D33: =D26*1000*Supuestos!$B$5 -> 545642.5
A34: CAPEX PV (MXN) | C34: =C33*Supuestos!$B$4 -> 12548250 | D34: =D33*Supuestos!$B$4 -> 9576025.9
A35: CAPEX BESS (USD) | C35: =C29*1000*Supuestos!$B$7 -> 549360 | D35: =D29*1000*Supuestos!$B$7 -> 549360
A36: CAPEX BESS (MXN) | C36: =C35*Supuestos!$B$4 -> 9641268 | D36: =D35*Supuestos!$B$4 -> 9641268
A37: — Autoabasto TALA / ENEL (vence 2032) —
A38: Beneficio autoabasto actual ($/año) | C38: 0 | D38: =C38 -> 0
A39: Gasto sin autoabasto — CFE pleno ($/año) | C39: =$N$19+C38 -> 15152838 | D39: =$N$19+D38 -> 15152838
A40: Gasto real hoy (con autoabasto) ($/año) | C40: =C39-C38 -> 15152838 | D40: =D39-D38 -> 15152838
A41: Generación PV año 1 (kWh) | C41: =C72 -> 1649771.2 | D41: =C89 -> 1259000.4
A42: Energía facturada al PPA (kWh) | C42: =K72 -> 1616886.2 | D42: =K89 -> 1259003.4
...

Sheet Proplasa
A1: GEPP Proplasa — Propuesta Solar + BESS | GDMTH (V. de México Norte) | Cuautitlán Izcalli, Méx. (montos MXN sin IVA)
A3: 1. DATOS BASE — últimos 12 meses reales (recibos CFE, sin IVA)
A4: Mes | B4: may-25 | C4: jun-25 | D4: jul-25 | E4: ago-25 | F4: sep-25 | G4: oct-25 | H4: nov-25 | I4: dic-25 | J4: ene-26 | K4: feb-26 | L4: mar-26 | M4: abr-26 | N4: TOTAL
A5: Consumo Base (kWh) | B5: 3062070 | C5: 2851900 | D5: 2393563 | E5: 2871886 | F5: 2475285 | G5: 2270491 | H5: 2403501 | I5: 2273858 | J5: 2435462 | K5: 2403239 | L5: 2852898 | M5: 2449911 | N5: =SUM(B5:M5) -> 30744064
A6: Consumo Intermedia (kWh) | B6: 5295526 | C6: 4915625 | D6: 4440610 | E6: 4951683 | F6: 4289473 | G6: 4217095 | H6: 3548867 | I6: 3514507 | J6: 4007070 | K6: 3515595 | L6: 4098354 | M6: 4443548 | N6: =SUM(B6:M6) -> 51237953
A7: Consumo Punta (kWh) | B7: 504661 | C7: 491592 | D7: 454077 | E7: 472890 | F7: 419682 | G7: 522441 | H7: 864535 | I7: 837753 | J7: 967455 | K7: 851537 | L7: 979353 | M7: 525209 | N7: =SUM(B7:M7) -> 7891185
A8: Consumo Total (kWh) | B8: =SUM(B5:B7) -> 8862257 | C8: =SUM(C5:C7) -> 8259117 | D8: =SUM(D5:D7) -> 7288250 | E8: =SUM(E5:E7) -> 8296459 | F8: =SUM(F5:F7) -> 7184440 | G8: =SUM(G5:G7) -> 7010027 | H8: =SUM(H5:H7) -> 6816903 | I8: =SUM(I5:I7) -> 6626118 | ... M8: =SUM(M5:M7) -> 7418668 | N8: =SUM(B8:M8) -> 89873202
A9: Dem. máx. en punta (kW) | B9: 11470 | C9: 11705 | D9: 9871 | E9: 11259 | F9: 9538 | G9: 10425 | H9: 10553 | I9: 9194 | J9: 10842 | K9: 10624 | L9: 11198 | M9: 11332 | N9: =MAX(B9:M9) -> 11705
A10: Dem. máx. mensual (kW) | B10: 13876 | C10: 12603 | D10: 10891 | E10: 12346 | F10: 11549 | G10: 10451 | H10: 12398 | I10: 12134 | J10: 12875 | K10: 13847 | L10: 14503 | M10: 13374 | N10: =MAX(B10:M10) -> 14503
A11: Días con punta | B11: 22 | C11: 21 | D11: 23 | E11: 21 | F11: 22 | G11: 23 | H11: 25 | I11: 27 | J11: 27 | K11: 24 | L11: 26 | M11: 23
A12: Horas punta/día | B12: 2 | C12: 2 | D12: 2 | E12: 2 | F12: 2 | G12: 2.43 | H12: 3.6 | I12: 3.7 | J12: 3.63 | K12: 3.67 | L12: 3.69 | M12: 2.26
A13: Días del mes | B13: 31 | C13: 30 | D13: 31 | E13: 31 | F13: 30 | G13: 31 | H13: 30 | I13: 31 | J13: 31 | K13: 28 | L13: 31 | M13: 30
A14: Tarifa Base ($/kWh) | B14: 1.1749 | C14: 1.1983 | D14: 1.2133 | E14: 1.2147 | F14: 1.2095 | G14: 1.2095 | H14: 1.1791 | I14: 1.1301 | J14: 1.106 | K14: 1.1065 | L14: 1.1071 | M14: 1.107
A15: Tarifa Intermedia ($/kWh) | B15: 1.9422 | C15: 1.9837 | D15: 2.0106 | E15: 2.0131 | F15: 2.0005 | G15: 2.0006 | H15: 1.9464 | I15: 1.859 | J15: 1.8185 | K15: 1.8194 | L15: 1.8204 | M15: 1.8204
A16: Tarifa Punta ($/kWh) | B16: 2.273 | C16: 2.3224 | D16: 2.3544 | E16: 2.3574 | F16: 2.3417 | G16: 2.3417 | H16: 2.2773 | I16: 2.1734 | J16: 2.1258 | K16: 2.1269 | L16: 2.1281 | M16: 2.128
A17: Tarifa Capacidad ($/kW·mes) | B17: 432.62 | C17: 442.9 | D17: 449.54 | E17: 450.17 | F17: 446.05 | G17: 446.05 | H17: 432.66 | I17: 411.03 | J17: 401.78 | K17: 402.01 | L17: 402.26 | M17: 402.24
A18: Tarifa Distribución ($/kW·mes) | B18: 91.12 | C18: 91.12 | D18: 91.12 | E18: 91.12 | F18: 91.12 | G18: 91.12 | H18: 91.12 | I18: 91.12 | J18: 86.15 | K18: 86.15 | L18: 86.15 | M18: 86.15
A19: Gasto actual facturado ($ MXN) | B19: 18374851 | C19: 19150128 | D19: 16543765 | E19: 18816263 | F19: 16458917 | G19: 16143663 | H19: 15535451 | I19: 14564709 | J19: 15688788 | K19: 14520758 | L19: 18689765 | M19: 17763059 | N19: =SUM(B19:M19) -> 202250117
A20: Umbral de demanda (kW) | B20: =B8/(24*B13*Supuestos!$B$15) -> 20897.607 | C20: =C8/(24*C13*Supuestos!$B$15) -> 20124.554 | D20: =D8/(24*D13*Supuestos!$B$15) -> 17186.026 | E20: =E8/(24*E13*Supuestos!$B$15) -> 19563.429 | F20: =F8/(24*F13*Supuestos!$B$15) -> 17505.945 | G20: =G8/(24*G13*Supuestos!$B$15) -> 16529.964 | H20: =H8/(24*H13*Supuestos!$B$15) -> 16610.387 | I20: =I8/(24*I13*Supuestos!$B$15) -> 15624.689 | ... M20: =M8/(24*M13*Supuestos!$B$15) -> 18076.676
A21: Yield PV (kWh/kWp) | B21: 143.096 | C21: 133.92 | D21: 135.16 | E21: 126.48 | F21: 119.52 | G21: 131.688 | H21: 136.56 | I21: 130.944 | J21: 142.848 | K21: 139.104 | L21: 170.128 | M21: 150.72 | N21: =SUM(B21:M21) -> 1660.168
A23: 2. SISTEMA PROPUESTO — Opción 1 y Opción 2 (amarillo = editable)
A24: Concepto | C24: OPCIÓN 1 — Autoconsumo | D24: OPCIÓN 2 — GD Medición Neta
A25: Esquema legal | C25: Autoconsumo interconectado (permiso CNE simplificado) | D25: Generación Distribuida <0.7 MW (sin permiso)
A26: Potencia PV (kWp DC) | C26: 3848.9 | D26: 2518.35
A27: Superficie requerida (m²) | C27: =C26*Supuestos!$B$24 -> 15395.6 | D27: =D26*Supuestos!$B$24 -> 10073.4
A28: BESS potencia (kW) | C28: 11787 | D28: 11787
A29: BESS capacidad (kWh) | C29: 23574 | D29: 23574
A30: Energía útil BESS (kWh) | C30: =C29*Supuestos!$B$13*SQRT(Supuestos!$B$14) -> 22173.8 | D30: =D29*Supuestos!$B$13*SQRT(Supuestos!$B$14) -> 22173.8
A31: Precio PPA (MXN/kWh, año 1) | C31: 1.3526645 | D31: 1.6148562
A32: Participación inversionista BESS (%) | C32: =Supuestos!$B$17 -> 0.5 | D32: =Supuestos!$B$17 -> 0.5
A33: CAPEX PV (USD) | C33: =C26*1000*Supuestos!$B$5 -> 2501785 | D33: =D26*1000*Supuestos!$B$5 -> 1636927.5
A34: CAPEX PV (MXN) | C34: =C33*Supuestos!$B$4 -> 43906327 | D34: =D33*Supuestos!$B$4 -> 28728078
A35: CAPEX BESS (USD) | C35: =C29*1000*Supuestos!$B$7 -> 6600720 | D35: =D29*1000*Supuestos!$B$7 -> 6600720
A36: CAPEX BESS (MXN) | C36: =C35*Supuestos!$B$4 -> 115842636 | D36: =D35*Supuestos!$B$4 -> 115842636
A37: — Autoabasto TALA / ENEL (vence 2032) —
A38: Beneficio autoabasto actual ($/año) | C38: 57664106 | D38: =C38 -> 57664106
A39: Gasto sin autoabasto — CFE pleno ($/año) | C39: =$N$19+C38 -> 2.5991422e+08 | D39: =$N$19+D38 -> 2.5991422e+08
A40: Gasto real hoy (con autoabasto) ($/año) | C40: =C39-C38 -> 202250117 | D40: =D39-D38 -> 202250117
A41: Generación PV año 1 (kWh) | C41: =C72 -> 6389820.6 | D41: =C89 -> 4180884.1
A42: Energía facturada al PPA (kWh) | C42: =K72 -> 6389820.6 | D42: =K89 -> 4180884.1
...
