Workbook

Sheet Resumen
A1: GEPP — PROPUESTA PROPLASA (3 SITIOS: Preforma 1, Preforma 2, Tapa) | MXN sin IVA | jul-2026
A3: Sitio | B3: Opción / Esquema | C3: PV (kWp) | D3: BESS (kW) | E3: BESS (kWh) | F3: Gen (kWh/año) | G3: Gasto real hoy ($/año) | H3: Beneficio autoab. ($/año, →2032) | I3: Ahorro bruto ($) | J3: Pago PPA ($) | K3: Pago partic. ($) | L3: AHORRO NETO GEPP ($) | M3: % bruto | N3: % neto | O3: PPA (MXN/kWh) | P3: TIR PV | Q3: TIR BESS @50%
A4: Proplasa · Preforma 1 | B4: Op1: Autoconsumo | C4: ='Preforma 1'!C26 -> 681.2 | D4: ='Preforma 1'!C28 -> 2080 | E4: ='Preforma 1'!C29 -> 4159 | F4: ='Preforma 1'!C41 -> 1130906.4 | G4: ='Preforma 1'!N19 -> 32178329 | H4: ='Preforma 1'!C38 -> 7886060.9 | I4: ='Preforma 1'!C45 -> 8780166.5 | J4: ='Preforma 1'!C46 -> 1249199.3 | K4: ='Preforma 1'!C47 -> 3367873.7 | L4: ='Preforma 1'!C48 -> 4163093.5 | M4: ='Preforma 1'!C49 -> 0.27285961 | N4: ='Preforma 1'!C50 -> 0.12937569 | O4: ='Preforma 1'!C31 -> 1.1046 | P4: ='Preforma 1'!C51 -> 0.14109903 | Q4: ='Preforma 1'!C52 -> 0.13491917
B5: Op2: GD Medición Neta | C5: ='Preforma 1'!D26 -> 839.45 | D5: ='Preforma 1'!D28 -> 2080 | E5: ='Preforma 1'!D29 -> 4159 | F5: ='Preforma 1'!D41 -> 1393628 | G5: ='Preforma 1'!N19 -> 32178329 | H5: ='Preforma 1'!C38 -> 7886060.9 | I5: ='Preforma 1'!D45 -> 9255107.2 | J5: ='Preforma 1'!D46 -> 1539401.5 | K5: ='Preforma 1'!D47 -> 3367873.7 | L5: ='Preforma 1'!D48 -> 4347832 | M5: ='Preforma 1'!D49 -> 0.28761926 | N5: ='Preforma 1'!D50 -> 0.13511677 | O5: ='Preforma 1'!D31 -> 1.1046 | P5: ='Preforma 1'!D51 -> 0.14109903 | Q5: ='Preforma 1'!D52 -> 0.13491917
A6: Proplasa · Preforma 2 | B6: Op1: Autoconsumo | C6: ='Preforma 2'!C26 -> 1912 | D6: ='Preforma 2'!C28 -> 5837 | E6: ='Preforma 2'!C29 -> 11674 | F6: ='Preforma 2'!C41 -> 3174241.2 | G6: ='Preforma 2'!N19 -> 1.0213677e+08 | H6: ='Preforma 2'!C38 -> 27268065 | I6: ='Preforma 2'!C45 -> 24644122 | J6: ='Preforma 2'!C46 -> 3506266.8 | K6: ='Preforma 2'!C47 -> 9452911.4 | L6: ='Preforma 2'!C48 -> 11684944 | M6: ='Preforma 2'!C49 -> 0.2412855 | N6: ='Preforma 2'!C50 -> 0.11440487 | O6: ='Preforma 2'!C31 -> 1.1046 | P6: ='Preforma 2'!C51 -> 0.14109903 | Q6: ='Preforma 2'!C52 -> 0.13490802
B7: Op2: GD Medición Neta | C7: ='Preforma 2'!D26 -> 839.45 | D7: ='Preforma 2'!D28 -> 5837 | E7: ='Preforma 2'!D29 -> 11674 | F7: ='Preforma 2'!D41 -> 1393628 | G7: ='Preforma 2'!N19 -> 1.0213677e+08 | H7: ='Preforma 2'!C38 -> 27268065 | I7: ='Preforma 2'!D45 -> 21425183 | J7: ='Preforma 2'!D46 -> 1539401.5 | K7: ='Preforma 2'!D47 -> 9452911.4 | L7: ='Preforma 2'!D48 -> 10432870 | M7: ='Preforma 2'!D49 -> 0.20976954 | N7: ='Preforma 2'!D50 -> 0.10214607 | O7: ='Preforma 2'!D31 -> 1.1046 | P7: ='Preforma 2'!D51 -> 0.14109903 | Q7: ='Preforma 2'!D52 -> 0.13490802
A8: Proplasa · Tapa | B8: Op1: Autoconsumo | C8: =Tapa!C26 -> 1255.7 | D8: =Tapa!C28 -> 3870 | E8: =Tapa!C29 -> 7741 | F8: =Tapa!C41 -> 2084673 | G8: =Tapa!N19 -> 63523603 | H8: =Tapa!C38 -> 22509980 | I8: =Tapa!C45 -> 16298623 | J8: =Tapa!C46 -> 2302729.7 | K8: =Tapa!C47 -> 6265006.5 | L8: =Tapa!C48 -> 7730886.6 | M8: =Tapa!C49 -> 0.25657586 | N8: =Tapa!C50 -> 0.12170101 | O8: =Tapa!C31 -> 1.1046 | P8: =Tapa!C51 -> 0.14109903 | Q8: =Tapa!C52 -> 0.13479034
B9: Op2: GD Medición Neta | C9: =Tapa!D26 -> 839.45 | D9: =Tapa!D28 -> 3870 | E9: =Tapa!D29 -> 7741 | F9: =Tapa!D41 -> 1393628 | G9: =Tapa!N19 -> 63523603 | H9: =Tapa!C38 -> 22509980 | I9: =Tapa!D45 -> 15049373 | J9: =Tapa!D46 -> 1539401.5 | K9: =Tapa!D47 -> 6265006.5 | L9: =Tapa!D48 -> 7244964.9 | M9: =Tapa!D49 -> 0.23690994 | N9: =Tapa!D50 -> 0.11405154 | O9: =Tapa!D31 -> 1.1046 | P9: =Tapa!D51 -> 0.14109903 | Q9: =Tapa!D52 -> 0.13479034
A11: PORTAFOLIO | B11: Suma Opción 1 | C11: =C4+C6+C8 -> 3848.9 | D11: =D4+D6+D8 -> 11787 | E11: =E4+E6+E8 -> 23574 | F11: =F4+F6+F8 -> 6389820.6 | G11: =G4+G6+G8 -> 1.978387e+08 | H11: =H4+H6+H8 -> 57664106 | I11: =I4+I6+I8 -> 49722911 | J11: =J4+J6+J8 -> 7058195.9 | ... L11: =L4+L6+L8 -> 23578924
B12: Suma Opción 2 | C12: =C5+C7+C9 -> 2518.35 | D12: =D5+D7+D9 -> 11787 | E12: =E5+E7+E9 -> 23574 | F12: =F5+F7+F9 -> 4180884.1 | G12: =G5+G7+G9 -> 1.978387e+08 | H12: =H5+H7+H9 -> 57664106 | I12: =I5+I7+I9 -> 45729663 | J12: =J5+J7+J9 -> 4618204.6 | ... L12: =L5+L7+L9 -> 22025667
A14: Nota: "Gasto real hoy" ya refleja el descuento de autoabasto; el "Beneficio autoab." (naranja) se pierde en 2032 → el gasto real del cliente salta en 2033 (ver proyección 20 años de cada sitio). Nuestro ahorro $ es el hedge.

Sheet Supuestos
A1: SUPUESTOS DEL MODELO — editar celdas amarillas (todo sin IVA)
A4: Tipo de cambio (MXN/USD) | B4: 17.55 | C4: MXN/USD
A5: Precio de venta PV (USD/Wp) | B5: 0.65 | C5: USD/Wp
A6: Costo duro PV — informativo (USD/Wp) | B6: 0.5 | C6: USD/Wp
A7: Precio BESS instalado (USD/Wh) | B7: 0.28 | C7: USD/Wh
A8: Costo FOB BESS — informativo (USD/Wh) | B8: 0.18 | C8: USD/Wh
A9: Escalación tarifas CFE (anual) | B9: 0.04 | C9: %
A10: Escalación precio PPA (anual) | B10: 0.04 | C10: %
A11: Degradación PV (anual) | B11: 0.005 | C11: %
A12: Degradación BESS (anual) | B12: 0.0125 | C12: %
A13: Profundidad de descarga BESS (DoD) | B13: 0.96
A14: Eficiencia round-trip BESS (RTE) | B14: 0.96
A15: Factor de carga p/ umbral de demanda | B15: 0.57
A16: Meses sin ahorro BESS al año (merma de riesgo) | B16: 2 | C16: meses
A17: Participación del inversionista en ahorro BESS | B17: 0.5 | C17: %
A18: Plazo PPA / venta de energía PV (años) | B18: 15 | C18: años
A19: Plazo BESS / participación en ahorro (años) | B19: 15 | C19: años
A20: Horizonte de análisis (años) | B20: 20 | C20: años
A21: Tasa de descuento / WACC | B21: 0.12 | C21: %
A22: O&M PV (MXN/kWp·año) | B22: 310 | C22: MXN/kWp
A23: O&M BESS (MXN/kWh·año) | B23: 180 | C23: MXN/kWh
A24: Densidad de instalación (m²/kWp) | B24: 4 | C24: m²/kWp
A25: Año base del modelo (Año 1) | B25: 2026 | C25: año
A26: Año de término autoabasto TALA / ENEL | B26: 2032 | C26: año
A29: SITIOS — recurso solar y superficie
A30: Sitio | B30: Municipio | C30: Tarifa | D30: Yield (kWh/kWp·año) | E30: Superficie disp. (m²)
A31: Proplasa · Preforma 1 | B31: Cuautitlán Izcalli, Méx. | C31: GDMTH (V. de México Norte) | D31: 1660 | E31: —
A32: Proplasa · Preforma 2 | B32: Cuautitlán Izcalli, Méx. | C32: GDMTH (V. de México Norte) | D32: 1660 | E32: —
A33: Proplasa · Tapa | B33: Cuautitlán Izcalli, Méx. | C33: GDMTH (V. de México Norte) | D33: 1660 | E33: —
A36: SUPUESTOS Y NOTAS CLAVE
A37: • Baseline: últimos 12 meses reales may-25 → abr-26 (recibos CFE, sin IVA).
A38: • Autoabasto TALA (Ixtlahuacán, zafra) y ENEL (Proplasa) vencen 2032. Su beneficio actual se
A39: cuantifica por sitio (fila "Beneficio autoabasto") y aparece en la proyección 20 años como la
A40: brecha entre "Gasto CFE pleno" y "Gasto real"; esa brecha se cierra en 2033 → el gasto real del
A41: cliente DA UN SALTO. El ahorro $ de nuestro sistema (PPA fijo) no cambia, por lo que cubre un %
A42: menor de un recibo mayor, pero es justo el hedge que amortigua ese salto. Editar beneficio y año.
A43: • Plazo PPA y plazo BESS ahora son independientes (celdas B18/B19). Ej.: 12 años PPA + 20 de
A44: participación en ahorro BESS. Tras el plazo PPA el ahorro PV queda 100% para GEPP (pago=0).
A45: • TIR nominal MXN, pre-IVA, sin apalancamiento, sobre precio de venta. PPA resuelto p/ TIR PV ~14%.
A46: • Marco legal: Ley del Sector Eléctrico (DOF 18-mar-2025). GD Exento <0.7 MW sin permiso (Art. 30).
...

Sheet Preforma 1
A1: GEPP Proplasa · Preforma 1 — Propuesta Solar + BESS | GDMTH (V. de México Norte) | Cuautitlán Izcalli, Méx. (MXN sin IVA)
A3: 1. DATOS BASE — últimos 12 meses reales (recibos CFE, sin IVA)
A4: Mes | B4: may-25 | C4: jun-25 | D4: jul-25 | E4: ago-25 | F4: sep-25 | G4: oct-25 | H4: nov-25 | I4: dic-25 | J4: ene-26 | K4: feb-26 | L4: mar-26 | M4: abr-26 | N4: TOTAL
A5: Consumo Base (kWh) | B5: 546627 | C5: 467527 | D5: 414209 | E5: 511027 | F5: 471225 | G5: 435183 | H5: 431457 | I5: 395911 | J5: 455237 | K5: 476589 | L5: 535513 | M5: 497333 | N5: =SUM(B5:M5) -> 5637838
A6: Consumo Intermedia (kWh) | B6: 924218 | C6: 810870 | D6: 746631 | E6: 868483 | F6: 799977 | G6: 788394 | H6: 617240 | I6: 618556 | J6: 729971 | K6: 681958 | L6: 750251 | M6: 867045 | N6: =SUM(B6:M6) -> 9203594
A7: Consumo Punta (kWh) | B7: 89553 | C7: 82141 | D7: 74300 | E7: 84864 | F7: 80458 | G7: 98384 | H7: 150654 | I7: 146212 | J7: 183178 | K7: 167798 | L7: 182294 | M7: 108027 | N7: =SUM(B7:M7) -> 1447863
A8: Consumo Total (kWh) | B8: =SUM(B5:B7) -> 1560398 | C8: =SUM(C5:C7) -> 1360538 | D8: =SUM(D5:D7) -> 1235140 | E8: =SUM(E5:E7) -> 1464374 | F8: =SUM(F5:F7) -> 1351660 | G8: =SUM(G5:G7) -> 1321961 | H8: =SUM(H5:H7) -> 1199351 | I8: =SUM(I5:I7) -> 1160679 | ... M8: =SUM(M5:M7) -> 1472405 | N8: =SUM(B8:M8) -> 16289295
A9: Dem. máx. en punta (kW) | B9: 1654 | C9: 1465 | D9: 1582 | E9: 1515 | F9: 2279 | G9: 1750 | H9: 2026 | I9: 2124 | J9: 1892 | K9: 1903 | L9: 1771 | M9: 1579 | N9: =MAX(B9:M9) -> 2279
A10: Dem. máx. mensual (kW) | B10: 1700 | C10: 1532 | D10: 1672 | E10: 1568 | F10: 2356 | G10: 1832 | H10: 2026 | I10: 2124 | J10: 1930 | K10: 1936 | L10: 1793 | M10: 1622 | N10: =MAX(B10:M10) -> 2356
A11: Días con punta | B11: 22 | C11: 21 | D11: 23 | E11: 21 | F11: 22 | G11: 23 | H11: 25 | I11: 27 | J11: 27 | K11: 24 | L11: 26 | M11: 23
A12: Horas punta/día | B12: 2 | C12: 2 | D12: 2 | E12: 2 | F12: 2 | G12: 2.43 | H12: 3.6 | I12: 3.7 | J12: 3.63 | K12: 3.67 | L12: 3.69 | M12: 2.26
A13: Días del mes | B13: 31 | C13: 30 | D13: 31 | E13: 31 | F13: 30 | G13: 31 | H13: 30 | I13: 31 | J13: 31 | K13: 28 | L13: 31 | M13: 30
A14: Tarifa Base ($/kWh) | B14: 1.1749 | C14: 1.1983 | D14: 1.2133 | E14: 1.2147 | F14: 1.2095 | G14: 1.2095 | H14: 1.1791 | I14: 1.1301 | J14: 1.106 | K14: 1.1065 | L14: 1.1071 | M14: 1.107
A15: Tarifa Intermedia ($/kWh) | B15: 1.9422 | C15: 1.9837 | D15: 2.0106 | E15: 2.0131 | F15: 2.0005 | G15: 2.0006 | H15: 1.9464 | I15: 1.859 | J15: 1.8185 | K15: 1.8194 | L15: 1.8204 | M15: 1.8204
A16: Tarifa Punta ($/kWh) | B16: 2.273 | C16: 2.3224 | D16: 2.3544 | E16: 2.3574 | F16: 2.3417 | G16: 2.3417 | H16: 2.2773 | I16: 2.1734 | J16: 2.1258 | K16: 2.1269 | L16: 2.1281 | M16: 2.128
A17: Tarifa Capacidad ($/kW·mes) | B17: 432.62 | C17: 442.9 | D17: 449.54 | E17: 450.17 | F17: 446.05 | G17: 446.05 | H17: 432.66 | I17: 411.03 | J17: 401.78 | K17: 402.01 | L17: 402.26 | M17: 402.24
A18: Tarifa Distribución ($/kW·mes) | B18: 91.12 | C18: 91.12 | D18: 91.12 | E18: 91.12 | F18: 91.12 | G18: 91.12 | H18: 91.12 | I18: 91.12 | J18: 86.15 | K18: 86.15 | L18: 86.15 | M18: 86.15
A19: Gasto actual facturado ($ MXN) | B19: 3302499.8 | C19: 2709232.8 | D19: 2381024.9 | E19: 2985577.8 | F19: 2695900.3 | G19: 2651342.2 | H19: 2280746.1 | I19: 2132953.9 | J19: 2570565.3 | K19: 2521062.4 | L19: 2806680.9 | M19: 3140742.8 | N19: =SUM(B19:M19) -> 32178329
A20: Umbral de demanda (kW) | B20: =B8/(24*B13*Supuestos!$B$15) -> 3679.4897 | C20: =C8/(24*C13*Supuestos!$B$15) -> 3315.1511 | D20: =D8/(24*D13*Supuestos!$B$15) -> 2912.5165 | E20: =E8/(24*E13*Supuestos!$B$15) -> 3453.0607 | F20: =F8/(24*F13*Supuestos!$B$15) -> 3293.5185 | G20: =G8/(24*G13*Supuestos!$B$15) -> 3117.2444 | H20: =H8/(24*H13*Supuestos!$B$15) -> 2922.3952 | I20: =I8/(24*I13*Supuestos!$B$15) -> 2736.9341 | ... M20: =M8/(24*M13*Supuestos!$B$15) -> 3587.7315
A21: Yield PV (kWh/kWp) | B21: 143.096 | C21: 133.92 | D21: 135.16 | E21: 126.48 | F21: 119.52 | G21: 131.688 | H21: 136.56 | I21: 130.944 | J21: 142.848 | K21: 139.104 | L21: 170.128 | M21: 150.72 | N21: =SUM(B21:M21) -> 1660.168
A23: 2. SISTEMA PROPUESTO — Opción 1 y Opción 2 (amarillo = editable)
A24: Concepto | C24: OPCIÓN 1 — Autoconsumo | D24: OPCIÓN 2 — GD Medición Neta
A25: Esquema legal | C25: Autoconsumo interconectado (permiso CNE simplificado) | D25: Generación Distribuida <0.7 MW (sin permiso)
A26: Potencia PV (kWp DC) | C26: 681.2 | D26: 839.45
A27: Superficie requerida (m²) | C27: =C26*Supuestos!$B$24 -> 2724.8 | D27: =D26*Supuestos!$B$24 -> 3357.8
A28: BESS potencia (kW) | C28: 2080 | D28: 2080
A29: BESS capacidad (kWh) | C29: 4159 | D29: 4159
A30: Energía útil BESS (kWh) | C30: =C29*Supuestos!$B$13*SQRT(Supuestos!$B$14) -> 3911.9723 | D30: =D29*Supuestos!$B$13*SQRT(Supuestos!$B$14) -> 3911.9723
A31: Precio PPA (MXN/kWh, año 1) | C31: 1.3526645 | D31: 1.6148562
A32: Participación inversionista BESS (%) | C32: =Supuestos!$B$17 -> 0.5 | D32: =Supuestos!$B$17 -> 0.5
A33: CAPEX PV (USD) | C33: =C26*1000*Supuestos!$B$5 -> 442780 | D33: =D26*1000*Supuestos!$B$5 -> 545642.5
A34: CAPEX PV (MXN) | C34: =C33*Supuestos!$B$4 -> 7770789 | D34: =D33*Supuestos!$B$4 -> 9576025.9
A35: CAPEX BESS (USD) | C35: =C29*1000*Supuestos!$B$7 -> 1164520 | D35: =D29*1000*Supuestos!$B$7 -> 1164520
A36: CAPEX BESS (MXN) | C36: =C35*Supuestos!$B$4 -> 20437326 | D36: =D35*Supuestos!$B$4 -> 20437326
A37: — Autoabasto TALA / ENEL (vence 2032) —
A38: Beneficio autoabasto actual ($/año) | C38: 7886060.9 | D38: =C38 -> 7886060.9
A39: Gasto sin autoabasto — CFE pleno ($/año) | C39: =$N$19+C38 -> 40064390 | D39: =$N$19+D38 -> 40064390
A40: Gasto real hoy (con autoabasto) ($/año) | C40: =C39-C38 -> 32178329 | D40: =D39-D38 -> 32178329
A41: Generación PV año 1 (kWh) | C41: =C72 -> 1130906.4 | D41: =C89 -> 1393628
A42: Energía facturada al PPA (kWh) | C42: =K72 -> 1130906.4 | D42: =K89 -> 1393628
...

Sheet Preforma 2
A1: GEPP Proplasa · Preforma 2 — Propuesta Solar + BESS | GDMTH (V. de México Norte) | Cuautitlán Izcalli, Méx. (MXN sin IVA)
A3: 1. DATOS BASE — últimos 12 meses reales (recibos CFE, sin IVA)
A4: Mes | B4: may-25 | C4: jun-25 | D4: jul-25 | E4: ago-25 | F4: sep-25 | G4: oct-25 | H4: nov-25 | I4: dic-25 | J4: ene-26 | K4: feb-26 | L4: mar-26 | M4: abr-26 | N4: TOTAL
A5: Consumo Base (kWh) | B5: 1554976 | C5: 1461034 | D5: 1213977 | E5: 1460355 | F5: 1257774 | G5: 1080780 | H5: 1215444 | I5: 1136000 | J5: 1127389 | K5: 1258745 | L5: 1582579 | M5: 1391931 | N5: =SUM(B5:M5) -> 15740984
A6: Consumo Intermedia (kWh) | B6: 2674916 | C6: 2511016 | D6: 2229430 | E6: 2480903 | F6: 2130853 | G6: 2010757 | H6: 1781412 | I6: 1717671 | J6: 1795542 | K6: 1870728 | L6: 2238743 | M6: 2472488 | N6: =SUM(B6:M6) -> 25914459
A7: Consumo Punta (kWh) | B7: 252409 | C7: 251483 | D7: 229493 | E7: 235656 | F7: 208228 | G7: 247787 | H7: 435452 | I7: 418355 | J7: 466031 | K7: 471567 | L7: 538917 | M7: 308716 | N7: =SUM(B7:M7) -> 4064094
A8: Consumo Total (kWh) | B8: =SUM(B5:B7) -> 4482301 | C8: =SUM(C5:C7) -> 4223533 | D8: =SUM(D5:D7) -> 3672900 | E8: =SUM(E5:E7) -> 4176914 | F8: =SUM(F5:F7) -> 3596855 | G8: =SUM(G5:G7) -> 3339324 | H8: =SUM(H5:H7) -> 3432308 | I8: =SUM(I5:I7) -> 3272026 | ... M8: =SUM(M5:M7) -> 4173135 | N8: =SUM(B8:M8) -> 45719537
A9: Dem. máx. en punta (kW) | B9: 6509 | C9: 6634 | D9: 5851 | E9: 6354 | F9: 5562 | G9: 4470 | H9: 6123 | I9: 5588 | J9: 6670 | K9: 6525 | L9: 6470 | M9: 6489 | N9: =MAX(B9:M9) -> 6670
A10: Dem. máx. mensual (kW) | B10: 6565 | C10: 6744 | D10: 5873 | E10: 6492 | F10: 6311 | G10: 4522 | H10: 6215 | I10: 6070 | J10: 6718 | K10: 6557 | L10: 6470 | M10: 6597 | N10: =MAX(B10:M10) -> 6744
A11: Días con punta | B11: 22 | C11: 21 | D11: 23 | E11: 21 | F11: 22 | G11: 23 | H11: 25 | I11: 27 | J11: 27 | K11: 24 | L11: 26 | M11: 23
A12: Horas punta/día | B12: 2 | C12: 2 | D12: 2 | E12: 2 | F12: 2 | G12: 2.43 | H12: 3.6 | I12: 3.7 | J12: 3.63 | K12: 3.67 | L12: 3.69 | M12: 2.26
A13: Días del mes | B13: 31 | C13: 30 | D13: 31 | E13: 31 | F13: 30 | G13: 31 | H13: 30 | I13: 31 | J13: 31 | K13: 28 | L13: 31 | M13: 30
A14: Tarifa Base ($/kWh) | B14: 1.1749 | C14: 1.1983 | D14: 1.2133 | E14: 1.2147 | F14: 1.2095 | G14: 1.2095 | H14: 1.1791 | I14: 1.1301 | J14: 1.106 | K14: 1.1065 | L14: 1.1071 | M14: 1.107
A15: Tarifa Intermedia ($/kWh) | B15: 1.9422 | C15: 1.9837 | D15: 2.0106 | E15: 2.0131 | F15: 2.0005 | G15: 2.0006 | H15: 1.9464 | I15: 1.859 | J15: 1.8185 | K15: 1.8194 | L15: 1.8204 | M15: 1.8204
A16: Tarifa Punta ($/kWh) | B16: 2.273 | C16: 2.3224 | D16: 2.3544 | E16: 2.3574 | F16: 2.3417 | G16: 2.3417 | H16: 2.2773 | I16: 2.1734 | J16: 2.1258 | K16: 2.1269 | L16: 2.1281 | M16: 2.128
A17: Tarifa Capacidad ($/kW·mes) | B17: 432.62 | C17: 442.9 | D17: 449.54 | E17: 450.17 | F17: 446.05 | G17: 446.05 | H17: 432.66 | I17: 411.03 | J17: 401.78 | K17: 402.01 | L17: 402.26 | M17: 402.24
A18: Tarifa Distribución ($/kW·mes) | B18: 91.12 | C18: 91.12 | D18: 91.12 | E18: 91.12 | F18: 91.12 | G18: 91.12 | H18: 91.12 | I18: 91.12 | J18: 86.15 | K18: 86.15 | L18: 86.15 | M18: 86.15
A19: Gasto actual facturado ($ MXN) | B19: 8530453.4 | C19: 10067365 | D19: 9371204.3 | E19: 10432413 | F19: 9148607.8 | G19: 8701905.6 | H19: 8980129.9 | I19: 8145664.8 | J19: 6171336.9 | K19: 6424180.2 | L19: 8245044 | M19: 7918464.6 | N19: =SUM(B19:M19) -> 1.0213677e+08
A20: Umbral de demanda (kW) | B20: =B8/(24*B13*Supuestos!$B$15) -> 10569.47 | C20: =C8/(24*C13*Supuestos!$B$15) -> 10291.26 | D20: =D8/(24*D13*Supuestos!$B$15) -> 8660.8659 | E20: =E8/(24*E13*Supuestos!$B$15) -> 9849.3539 | F20: =F8/(24*F13*Supuestos!$B$15) -> 8764.2666 | G20: =G8/(24*G13*Supuestos!$B$15) -> 7874.2784 | H20: =H8/(24*H13*Supuestos!$B$15) -> 8363.3236 | I20: =I8/(24*I13*Supuestos!$B$15) -> 7715.5867 | ... M20: =M8/(24*M13*Supuestos!$B$15) -> 10168.458
A21: Yield PV (kWh/kWp) | B21: 143.096 | C21: 133.92 | D21: 135.16 | E21: 126.48 | F21: 119.52 | G21: 131.688 | H21: 136.56 | I21: 130.944 | J21: 142.848 | K21: 139.104 | L21: 170.128 | M21: 150.72 | N21: =SUM(B21:M21) -> 1660.168
A23: 2. SISTEMA PROPUESTO — Opción 1 y Opción 2 (amarillo = editable)
A24: Concepto | C24: OPCIÓN 1 — Autoconsumo | D24: OPCIÓN 2 — GD Medición Neta
A25: Esquema legal | C25: Autoconsumo interconectado (permiso CNE simplificado) | D25: Generación Distribuida <0.7 MW (sin permiso)
A26: Potencia PV (kWp DC) | C26: 1912 | D26: 839.45
A27: Superficie requerida (m²) | C27: =C26*Supuestos!$B$24 -> 7648 | D27: =D26*Supuestos!$B$24 -> 3357.8
A28: BESS potencia (kW) | C28: 5837 | D28: 5837
A29: BESS capacidad (kWh) | C29: 11674 | D29: 11674
A30: Energía útil BESS (kWh) | C30: =C29*Supuestos!$B$13*SQRT(Supuestos!$B$14) -> 10980.612 | D30: =D29*Supuestos!$B$13*SQRT(Supuestos!$B$14) -> 10980.612
A31: Precio PPA (MXN/kWh, año 1) | C31: 1.3526645 | D31: 1.6148562
A32: Participación inversionista BESS (%) | C32: =Supuestos!$B$17 -> 0.5 | D32: =Supuestos!$B$17 -> 0.5
A33: CAPEX PV (USD) | C33: =C26*1000*Supuestos!$B$5 -> 1242800 | D33: =D26*1000*Supuestos!$B$5 -> 545642.5
A34: CAPEX PV (MXN) | C34: =C33*Supuestos!$B$4 -> 21811140 | D34: =D33*Supuestos!$B$4 -> 9576025.9
A35: CAPEX BESS (USD) | C35: =C29*1000*Supuestos!$B$7 -> 3268720 | D35: =D29*1000*Supuestos!$B$7 -> 3268720
A36: CAPEX BESS (MXN) | C36: =C35*Supuestos!$B$4 -> 57366036 | D36: =D35*Supuestos!$B$4 -> 57366036
A37: — Autoabasto TALA / ENEL (vence 2032) —
A38: Beneficio autoabasto actual ($/año) | C38: 27268065 | D38: =C38 -> 27268065
A39: Gasto sin autoabasto — CFE pleno ($/año) | C39: =$N$19+C38 -> 1.2940483e+08 | D39: =$N$19+D38 -> 1.2940483e+08
A40: Gasto real hoy (con autoabasto) ($/año) | C40: =C39-C38 -> 1.0213677e+08 | D40: =D39-D38 -> 1.0213677e+08
A41: Generación PV año 1 (kWh) | C41: =C72 -> 3174241.2 | D41: =C89 -> 1393628
A42: Energía facturada al PPA (kWh) | C42: =K72 -> 3174241.2 | D42: =K89 -> 1393628
...

Sheet Tapa
A1: GEPP Proplasa · Tapa — Propuesta Solar + BESS | GDMTH (V. de México Norte) | Cuautitlán Izcalli, Méx. (MXN sin IVA)
A3: 1. DATOS BASE — últimos 12 meses reales (recibos CFE, sin IVA)
A4: Mes | B4: may-25 | C4: jun-25 | D4: jul-25 | E4: ago-25 | F4: sep-25 | G4: oct-25 | H4: nov-25 | I4: dic-25 | J4: ene-26 | K4: feb-26 | L4: mar-26 | M4: abr-26 | N4: TOTAL
A5: Consumo Base (kWh) | B5: 960467 | C5: 923339 | D5: 765377 | E5: 900504 | F5: 746286 | G5: 754528 | H5: 756600 | I5: 741947 | J5: 881325 | K5: 805606 | L5: 960995 | M5: 891289 | N5: =SUM(B5:M5) -> 10088263
A6: Consumo Intermedia (kWh) | B6: 1696392 | C6: 1593739 | D6: 1464549 | E6: 1602297 | F6: 1358643 | G6: 1417944 | H6: 1150215 | I6: 1178280 | J6: 1481542 | K6: 1252899 | L6: 1426117 | M6: 1620825 | N6: =SUM(B6:M6) -> 17243442
A7: Consumo Punta (kWh) | B7: 162699 | C7: 157968 | D7: 150284 | E7: 152370 | F7: 130996 | G7: 176270 | H7: 278429 | I7: 273186 | J7: 365971 | K7: 303074 | L7: 335764 | M7: 207717 | N7: =SUM(B7:M7) -> 2694728
A8: Consumo Total (kWh) | B8: =SUM(B5:B7) -> 2819558 | C8: =SUM(C5:C7) -> 2675046 | D8: =SUM(D5:D7) -> 2380210 | E8: =SUM(E5:E7) -> 2655171 | F8: =SUM(F5:F7) -> 2235925 | G8: =SUM(G5:G7) -> 2348742 | H8: =SUM(H5:H7) -> 2185244 | I8: =SUM(I5:I7) -> 2193413 | ... M8: =SUM(M5:M7) -> 2719831 | N8: =SUM(B8:M8) -> 30026433
A9: Dem. máx. en punta (kW) | B9: 4081 | C9: 4146 | D9: 3935 | E9: 3868 | F9: 3761 | G9: 3121 | H9: 3661 | I9: 3968 | J9: 4272 | K9: 4136 | L9: 4183 | M9: 4106 | N9: =MAX(B9:M9) -> 4272
A10: Dem. máx. mensual (kW) | B10: 4308 | C10: 4228 | D10: 3987 | E10: 4012 | F10: 3791 | G10: 3433 | H10: 3772 | I10: 3985 | J10: 4350 | K10: 4251 | L10: 4350 | M10: 4250 | N10: =MAX(B10:M10) -> 4350
A11: Días con punta | B11: 22 | C11: 21 | D11: 23 | E11: 21 | F11: 22 | G11: 23 | H11: 25 | I11: 27 | J11: 27 | K11: 24 | L11: 26 | M11: 23
A12: Horas punta/día | B12: 2 | C12: 2 | D12: 2 | E12: 2 | F12: 2 | G12: 2.43 | H12: 3.6 | I12: 3.7 | J12: 3.63 | K12: 3.67 | L12: 3.69 | M12: 2.26
A13: Días del mes | B13: 31 | C13: 30 | D13: 31 | E13: 31 | F13: 30 | G13: 31 | H13: 30 | I13: 31 | J13: 31 | K13: 28 | L13: 31 | M13: 30
A14: Tarifa Base ($/kWh) | B14: 1.1749 | C14: 1.1983 | D14: 1.2133 | E14: 1.2147 | F14: 1.2095 | G14: 1.2095 | H14: 1.1791 | I14: 1.1301 | J14: 1.106 | K14: 1.1065 | L14: 1.1071 | M14: 1.107
A15: Tarifa Intermedia ($/kWh) | B15: 1.9422 | C15: 1.9837 | D15: 2.0106 | E15: 2.0131 | F15: 2.0005 | G15: 2.0006 | H15: 1.9464 | I15: 1.859 | J15: 1.8185 | K15: 1.8194 | L15: 1.8204 | M15: 1.8204
A16: Tarifa Punta ($/kWh) | B16: 2.273 | C16: 2.3224 | D16: 2.3544 | E16: 2.3574 | F16: 2.3417 | G16: 2.3417 | H16: 2.2773 | I16: 2.1734 | J16: 2.1258 | K16: 2.1269 | L16: 2.1281 | M16: 2.128
A17: Tarifa Capacidad ($/kW·mes) | B17: 432.62 | C17: 442.9 | D17: 449.54 | E17: 450.17 | F17: 446.05 | G17: 446.05 | H17: 432.66 | I17: 411.03 | J17: 401.78 | K17: 402.01 | L17: 402.26 | M17: 402.24
A18: Tarifa Distribución ($/kW·mes) | B18: 91.12 | C18: 91.12 | D18: 91.12 | E18: 91.12 | F18: 91.12 | G18: 91.12 | H18: 91.12 | I18: 91.12 | J18: 86.15 | K18: 86.15 | L18: 86.15 | M18: 86.15
A19: Gasto actual facturado ($ MXN) | B19: 6541898 | C19: 6373529.9 | D19: 4791535.4 | E19: 5398272.1 | F19: 4614409.2 | G19: 4790415.4 | H19: 4274575.5 | I19: 4286090.2 | J19: 5344856.9 | K19: 4464979.3 | L19: 6189354.3 | M19: 6453686.4 | N19: =SUM(B19:M19) -> 63523603
A20: Umbral de demanda (kW) | B20: =B8/(24*B13*Supuestos!$B$15) -> 6648.6465 | C20: =C8/(24*C13*Supuestos!$B$15) -> 6518.1433 | D20: =D8/(24*D13*Supuestos!$B$15) -> 5612.6438 | E20: =E8/(24*E13*Supuestos!$B$15) -> 6261.0144 | F20: =F8/(24*F13*Supuestos!$B$15) -> 5448.1603 | G20: =G8/(24*G13*Supuestos!$B$15) -> 5538.4409 | H20: =H8/(24*H13*Supuestos!$B$15) -> 5324.6686 | I20: =I8/(24*I13*Supuestos!$B$15) -> 5172.168 | ... M20: =M8/(24*M13*Supuestos!$B$15) -> 6627.2685
A21: Yield PV (kWh/kWp) | B21: 143.096 | C21: 133.92 | D21: 135.16 | E21: 126.48 | F21: 119.52 | G21: 131.688 | H21: 136.56 | I21: 130.944 | J21: 142.848 | K21: 139.104 | L21: 170.128 | M21: 150.72 | N21: =SUM(B21:M21) -> 1660.168
A23: 2. SISTEMA PROPUESTO — Opción 1 y Opción 2 (amarillo = editable)
A24: Concepto | C24: OPCIÓN 1 — Autoconsumo | D24: OPCIÓN 2 — GD Medición Neta
A25: Esquema legal | C25: Autoconsumo interconectado (permiso CNE simplificado) | D25: Generación Distribuida <0.7 MW (sin permiso)
A26: Potencia PV (kWp DC) | C26: 1255.7 | D26: 839.45
A27: Superficie requerida (m²) | C27: =C26*Supuestos!$B$24 -> 5022.8 | D27: =D26*Supuestos!$B$24 -> 3357.8
A28: BESS potencia (kW) | C28: 3870 | D28: 3870
A29: BESS capacidad (kWh) | C29: 7741 | D29: 7741
A30: Energía útil BESS (kWh) | C30: =C29*Supuestos!$B$13*SQRT(Supuestos!$B$14) -> 7281.216 | D30: =D29*Supuestos!$B$13*SQRT(Supuestos!$B$14) -> 7281.216
A31: Precio PPA (MXN/kWh, año 1) | C31: 1.3526645 | D31: 1.6148562
A32: Participación inversionista BESS (%) | C32: =Supuestos!$B$17 -> 0.5 | D32: =Supuestos!$B$17 -> 0.5
A33: CAPEX PV (USD) | C33: =C26*1000*Supuestos!$B$5 -> 816205 | D33: =D26*1000*Supuestos!$B$5 -> 545642.5
A34: CAPEX PV (MXN) | C34: =C33*Supuestos!$B$4 -> 14324398 | D34: =D33*Supuestos!$B$4 -> 9576025.9
A35: CAPEX BESS (USD) | C35: =C29*1000*Supuestos!$B$7 -> 2167480 | D35: =D29*1000*Supuestos!$B$7 -> 2167480
A36: CAPEX BESS (MXN) | C36: =C35*Supuestos!$B$4 -> 38039274 | D36: =D35*Supuestos!$B$4 -> 38039274
A37: — Autoabasto TALA / ENEL (vence 2032) —
A38: Beneficio autoabasto actual ($/año) | C38: 22509980 | D38: =C38 -> 22509980
A39: Gasto sin autoabasto — CFE pleno ($/año) | C39: =$N$19+C38 -> 86033582 | D39: =$N$19+D38 -> 86033582
A40: Gasto real hoy (con autoabasto) ($/año) | C40: =C39-C38 -> 63523603 | D40: =D39-D38 -> 63523603
A41: Generación PV año 1 (kWh) | C41: =C72 -> 2084673 | D41: =C89 -> 1393628
A42: Energía facturada al PPA (kWh) | C42: =K72 -> 2084673 | D42: =K89 -> 1393628
...
